Workbook

Sheet Model Flow
B1: ALUR MODEL (MODEL FLOW) - panduan praktis model keuangan FSL tanpa Sapphire, direvisi dari workbook v29 asli
B2: Semua angka di lembar ini adalah rumus yang membaca sel model (bukan ketikan). Klik teks biru bergaris bawah untuk melompat ke sel yang dimaksud. Nama lembar, nomor bagian dan alamat sel ditulis apa adanya (bahasa Inggris).
B3: Go to sheet: | C3: [Model Flow] | D3: Inputs | E3: FS Request | F3: Revenue | G3: Costs | H3: BUMN Synergy | I3: Capex | J3: Work. cap. | K3: Financing | L3: Funding | M3: Out: w/o BUMN | N3: Out: With BUMN | O3: Val: w/o BUMN | P3: Val: With BUMN | Q3: Proj. CF | R3: Proj. Summary | S3: Checks | T3: Source Data
B6: 1. MULAI DARI MANA - status model dan hasil utama (rumus hidup)
B7: Lembar Checks & Reconciliation bagian A menjawab tiga pertanyaan. Model ini adalah BASELINE REVISI: semua asumsi v29 dipertahankan kecuali perubahan yang diminta (tanggal valuasi, pinjaman LT, capex %, Badas, pendanaan). Karena itu sebagian baris sengaja berbeda dari v29; statusnya "Differs - requested change" dan setiap selisih dijelaskan (bagian D dan G).
B8: 1. Apakah model mereproduksi v29, selain perubahan yang diminta? | C8: ='Checks & Reconciliation'!$C$7 -> Differs - inputs / switches changed: 46 line(s) affected | H8: Checks & Reconciliation A
B9: Tingkat proyek: 16 blok bisnis v29 | C9: ='Checks & Reconciliation'!$C$8 -> YES - all 16 v29 business blocks reproduced (14 identical; 2 differ only through the LT loan interest in FY2026-27) | H9: Checks & Reconciliation A
B10: Jembatan v29 -> baseline revisi | C10: ='Checks & Reconciliation'!$C$9 -> Differs - inputs changed | H10: Checks & Reconciliation A
B11: 2. Apakah model lolos pemeriksaan integritas akuntansi dan keuangan? | C11: ='Checks & Reconciliation'!$C$12 -> YES - all 36 checks pass (balance sheet, cash, roll-forwards, funding sources = uses, tax, bridges, valuation, capex, Badas, summaries) | H11: Checks & Reconciliation A
B12: Peringatan tentang hasil | C12: ='Checks & Reconciliation'!$C$13 -> 1 warning(s) about the result - see section B | H12: Checks & Reconciliation A
B13: 3. Apakah ada masalah data sumber yang belum terselesaikan? | C13: ='Checks & Reconciliation'!$C$15 -> 13 v29 source issues documented; corrections ON: 0 of 13 - v29 treatment kept (incl. its 0.006 balance-sheet residual and negative fixed assets) | H13: Checks & Reconciliation A
B14: Item yang perlu dikonfirmasi | C14: ='Checks & Reconciliation'!$C$16 -> 33 item(s): provisional valuation / funding parameters, the LT loan terms, Badas FS data and open source questions | H14: Checks & Reconciliation A
B15: Perubahan yang aktif dan perubahan input Anda | C15: ='Checks & Reconciliation'!$C$18 -> Requested changes active: LT loan repaid FY2027 + equity = residual requirement | inputs changed vs the delivered baseline: 1 row(s) / switch(es) (Inputs column U) | Corrections ON: none | H15: Checks & Reconciliation A
B16: Kasus yang sedang berlaku | C16: ='Checks & Reconciliation'!$C$19 -> Scenario 1 | projects in the valuation: 15 of 19 | BUMN control: ON | valuation date 31-Dec-2026 | Badas IN the valuation (DUMMY) | H16: Checks & Reconciliation A
B18: Hasil utama (IDR miliar; tanggal valuasi 31-Des-2026). Nilai ekuitas = nilai; kebutuhan ekuitas = kas yang harus disetor pemegang saham. Keduanya BERBEDA.
B19: Hasil | C19: Dengan BUMN | D19: Tanpa BUMN | E19: Sel (Dengan BUMN) | F19: Sel (Tanpa BUMN)
B20: Nilai perusahaan (EV, 100%) | C20: ='Valuation — With BUMN'!$E$67 -> 4633.2655 | D20: ='Valuation — Without BUMN'!$E$67 -> 4121.4079 | E20: Valuation — With BUMN!E67 | F20: Valuation — Without BUMN!E67
B21: Nilai ekuitas untuk pemegang saham FSL | C21: ='Valuation — With BUMN'!$E$74 -> 3959.7433 | D21: ='Valuation — Without BUMN'!$E$74 -> 3536.8634 | E21: Valuation — With BUMN!E74 | F21: Valuation — Without BUMN!E74
B22: Nilai ekuitas (USD juta, kurs tahun valuasi) | C22: ='Valuation — With BUMN'!$E$75 -> 243.45178 | D22: ='Valuation — Without BUMN'!$E$75 -> 217.45241 | E22: Valuation — With BUMN!E75 | F22: Valuation — Without BUMN!E75
B23: Total kebutuhan ekuitas (kas yang harus disetor, semua tahun) | C23: ='Funding Requirement'!$E$21 -> 28.884163 | D23: ='Funding Requirement'!$F$21 -> 76.665204 | E23: Funding Requirement!E21 | F23: Funding Requirement!F21
B24: Tahun pertama ekuitas dibutuhkan | C24: ='Funding Requirement'!$E$23 -> 2027 | D24: ='Funding Requirement'!$F$23 -> 2027 | E24: Funding Requirement!E23 | F24: Funding Requirement!F23
B25: Kesenjangan pendanaan terbesar dalam satu tahun | C25: ='Funding Requirement'!$E$14 -> 28.884163 | D25: ='Funding Requirement'!$F$14 -> 76.665204 | E25: Funding Requirement!E14 | F25: Funding Requirement!F14
B26: Nilai skema BUMN yang menjadi hak FSL (EV Dengan - Tanpa BUMN) | C26: ='Valuation — With BUMN'!$E$116 -> 511.85758 | D26: IDR miliar | E26: Valuation — With BUMN!E116
B27: Badas (ilustratif, input DUMMY): NPV 100% pada tanggal valuasi | C27: ='Project Cash Flows'!$E$379 -> 14.116098 | D27: IDR miliar | E27: Project Cash Flows!E379
B28: Dua kasus dan jembatan di antara keduanya (FY2026, IDR miliar). Angka referensi: 494,571 (FSL tanpa BUMN) + 127,494 (kontribusi BUMN) = 622,065 (v29 Output_FSL!L44) - tidak berubah oleh revisi.
B29: Pendapatan FY2026 - kasus Tanpa BUMN | C29: ='FSL Output - Without BUMN'!J9 -> 494.57108 | D29: IDR miliar | E29: FSL Output - Without BUMN!J9
B30: Kontribusi BUMN FY2026 = pendapatan hak FSL dari skema operatorship P12-P14 | C30: ='BUMN Synergy Calculation'!J98 -> 127.49381 | D30: IDR miliar | E30: BUMN Synergy Calculation!J98
B31: Pendapatan FY2026 - kasus Dengan BUMN | C31: ='FSL Output - With BUMN'!J59 -> 622.06489 | D31: IDR miliar | E31: FSL Output - With BUMN!J59
B33: Urutan lembar dan fungsinya (nama lembar persis seperti di tab):
B34: Inputs | C34: Semua asumsi dan kontrol - satu-satunya lembar yang diedit. Kolom D = tipe (v29 / Derived / CHANGE / DUMMY / TO CONFIRM / Control / Placeholder); kolom U menandai nilai yang berbeda dari nilai yang diserahkan (Source Data, baris sama).
B35: FS Data Request | C35: Daftar data yang diminta dari studi kelayakan Badas (dan proyek funding-only / placeholder): definisi, satuan, status, sel Inputs tempat mengisi, baris perhitungan yang memakainya.
B36: Revenue Calculation | C36: Volume x tarif per bisnis dan proyek (E1-E4, P01-P11, P15-P19). A: tahun mulai dan bendera operasi. E: Badas (template).
B37: Cost Calculation | C37: Biaya pokok, beban usaha dan EBITDA per bisnis; D: Badas; E: ringkasan per kasus.
B38: BUMN Synergy Calculation | C38: Skema operatorship P12-P14: ekonomi per ton, hak FSL, bagian yang tetap di BUMN (informasi saja).
B39: Capex & Depreciation | C39: A: capex USD = total investasi x % belanja per tahun; A2: ringkasan sebelum / sesudah tanggal valuasi; B-C: kurs dan IDR; D-E: penyusutan; G: per bisnis (termasuk nilai buku); J: capex di luar laporan (funding request); K: tangkapan layar daftar proyek.
B40: Working Capital | C40: Piutang, persediaan, utang usaha per bisnis dan per kasus (metode v29).
B41: Financing | C41: Pinjaman lama (termasuk pinjaman LT 12 USD juta yang dilunasi 2027), fasilitas utang baru, utang proyek Badas, dividen (aturan v29), ekuitas, DSCR.
B42: Funding Requirement | C42: Arus kas (sumber dan penggunaan dana), kesenjangan pendanaan, utang, ekuitas residual, proyek capex-only, total kebutuhan ekuitas dan waktunya.
B43: FSL Output - Without BUMN | C43: Laba rugi, pajak, neraca, arus kas FSL tanpa skema BUMN; referensi FCFF / IRR v29.
B44: FSL Output - With BUMN | C44: Sama dengan skema BUMN P12-P14; bagian A: jembatan Tanpa BUMN + kontribusi BUMN = Dengan BUMN.
...

Sheet Inputs
B1: INPUTS - every assumption and control (edit only here)
B2: Blue text on a coloured fill = editable. Parameters: column E. Annual assumptions: one cell per year, columns H:T (G = pre-2024 / Dec-23). Type (column D): v29 / Derived / CHANGE (requested vs v29) / DUMMY / TO CONFIRM / Control. Column U flags cells that differ from the delivered value.
B3: Go to sheet: | C3: Model Flow | D3: [Inputs] | E3: FS Request | F3: Revenue | G3: Costs | H3: BUMN Synergy | I3: Capex | J3: Work. cap. | K3: Financing | L3: Funding | M3: Out: w/o BUMN | N3: Out: With BUMN | O3: Val: w/o BUMN | P3: Val: With BUMN | Q3: Proj. CF | R3: Proj. Summary | S3: Checks | T3: Source Data
B5: HOW TO USE THIS SHEET
B6: 1. Change only cells with blue text on a coloured fill. Black text = formula (do not edit); green text = link from another sheet. Column U flags a value that differs from the delivered value (kept on Source Data, same row).
B7: 2. As delivered the inputs are the REVISED BASELINE: every v29 assumption except the requested changes (type CHANGE): valuation date 31-Dec-2026, LT loan repaid in 2027, new equity = residual funding requirement. Capex = total investment x spending % (v29 timing).
B8: Checks & Reconciliation D compares every line with v29 and names the change behind each difference. To reproduce v29 exactly: LT loan repayment date 31-Dec-2025 (section 10) and equity basis 2 (section 1).
B9: 3. Annual assumptions have one cell per year (columns H:T; G = pre-2024 / 2023 base). Changing FY2028 changes only FY2028; growth rows carry the effect into later years. Type (column D): v29 / Derived / CHANGE / DUMMY / TO CONFIRM / Control / Placeholder.
B10: 4. Sections: 1 controls | 2 project register (valuation inclusion) | 5 projects (capex = total x %) | 10 financing incl. the LT loan | 12 valuation (WACC) | 13 Badas (DUMMY) | 14 pipeline placeholders | 15 funding-only projects | 16 optional v29 corrections (technical, all 0).
B11: 5. Badas FS data: the FS Data Request sheet lists every item with its cell here. Enter FS data only on this sheet - one authoritative cell per item; never paste over formulas.
B13: Colour key (column D = type)
C14: v29 | D14: Value taken from v29 (V29_Ruby_FM_Danantara.xlsm) or the value v29 applies (cell in column F)
C15: Derived | D15: Derived or interpreted from v29 data (derivation in column V)
C16: CHANGE | D16: User-requested change vs v29 (v29 value / cell in column F; reconciled on Checks & Reconciliation D)
C17: DUMMY | D17: DUMMY - REPLACE WITH FS DATA (Badas; listed on the FS Data Request sheet)
C18: TO CONFIRM | D18: Provisional assumption - not in v29 (register on Checks & Reconciliation section C)
C19: Control | D19: Switch or lever (delivered setting)
C20: Placeholder | D20: Future-project or funding-only input intentionally left blank
C21: formula | D21: Calculated cell (black); link from another sheet (green) - do not edit
B23: SECTIONS (click to jump)
B24: 1. CONTROLS - business cases, funding basis and sensitivity levers (project switches: section 2; Badas: 2 and 13; optional v29 corrections: 16)
B25: 2. PROJECT REGISTER - every business and project, its source, inclusion switch, timing and where it is modelled
B26: 3. GENERAL ASSUMPTIONS - dates, currency, units
B27: 4. EXISTING OPERATIONS (E1-E4) - volumes, tariffs, growth and existing-asset depreciation schedules
B28: 5. PROJECTS (P01-P11, P15) - operating assumptions, capex (total investment x annual spending %) and asset lives, project by project
B29: 6. OPERATING COSTS OF EXISTING BUSINESSES - FY2023 base x v29 uplift, then each year's growth; cost ratios
B30: 7. BUMN SYNERGIES (P12-P14) - SOE-level tariffs and unit costs by year, FSL margins, investment and working-capital requirements
B31: 8. SUSTAINING CAPEX AND CANCELLATION (all asset-owning businesses) - nil in v29
B32: 9. WORKING CAPITAL
B33: 10. FINANCING - existing loans (incl. the 12 USD mn LT loan, now repaid in 2027), new debt, committed funding, equity basis, dividends
B34: 11. TAX AND OWNERSHIP
... B40: 1. CONTROLS - business cases, funding basis and sensitivity levers (project switches: section 2; Badas: 2 and 13; optional v29 corrections: 16)
B41: Control | C41: Unit | D41: Type | E41: Parameter | F41: v29 source | U41: Diff | V41: Source and explanation
B42: Scenario selector | C42: code | D42: Control | E42: 1 | F42: Delivered setting (v29 Output_FSL!F27 = 1) | U42: =IF(E42='Source Data'!E42,"","changed") | V42: 1 = existing businesses + every project switched ON in section 2 (v29 saved case). 2 = existing businesses only (every project excluded).
B43: BUMN operatorship schemes (P12-P14) included in the With BUMN case | C43: 0 / 1 | D43: Control | E43: 1 | F43: Delivered setting (v29 Output_FSL!G35 = 1) | U43: =IF(E43='Source Data'!E43,"","changed") | V43: 1 = the With BUMN sheets include the FSL entitlement under the operatorship schemes (v29 saved case). 0 = both cases exclude them. The Without BUMN sheets always exclude them.
B44: Equity injection basis: 1 = equity required by the cash roll-forward, 2 = v29 schedule (100% of FY2026-27 project capex) | C44: code | D44: CHANGE | E44: 1 | F44: v29: 2 (Call Rights scenario 4, Calculation_FSL!L1498:M1498) | U44: =IF(E44='Source Data'!E44,"","changed") | V44: USER-REQUESTED CHANGE: v29 issues new shares equal to the FY2026-27 project capex whether or not cash is short. Revised: new equity = the funding gap left after internal cash, committed funding and debt (Funding Requirement). Set 2 to reproduce v29.
B45: Volume lever (% change applied to every volume in every year) | C45: % | D45: Control | E45: 0 | F45: Delivered setting | U45: =IF(E45='Source Data'!E45,"","changed") | V45: Sensitivity lever; 0% = inputs as entered.
B46: Tariff lever (% change applied to every FSL tariff and fee) | C46: % | D46: Control | E46: 0 | F46: Delivered setting | U46: =IF(E46='Source Data'!E46,"","changed") | V46: Sensitivity lever; 0% = inputs as entered.
B47: Operating cost lever (% change applied to cost of sales and operating expenses) | C47: % | D47: Control | E47: 0 | F47: Delivered setting | U47: =IF(E47='Source Data'!E47,"","changed") | V47: Sensitivity lever; 0% = inputs as entered.
B48: Project capex lever (% change applied to post-2023 project capex) | C48: % | D48: Control | E48: 0 | F48: Delivered setting | U48: =IF(E48='Source Data'!E48,"","changed") | V48: Sensitivity lever; 0% = inputs as entered.
...

Sheet FS Data Request
B1: FS DATA REQUEST - data needed from the Badas feasibility study (and for funding-only projects and pipeline placeholders)
B2: Each item is entered in ONE place only: the Inputs cell in column I (click to go there). This sheet only reads - never paste over it. Status turns to "Updated" once the Inputs value differs from the delivered DUMMY value.
B3: Go to sheet: | C3: Model Flow | D3: Inputs | E3: [FS Request] | F3: Revenue | G3: Costs | H3: BUMN Synergy | I3: Capex | J3: Work. cap. | K3: Financing | L3: Funding | M3: Out: w/o BUMN | N3: Out: With BUMN | O3: Val: w/o BUMN | P3: Val: With BUMN | Q3: Proj. CF | R3: Proj. Summary | S3: Checks | T3: Source Data
C5: Badas items still DUMMY / provisional (count) | E5: =COUNTIF(H9:H38,"DUMMY*")+COUNTIF(H9:H38,"PROVISIONAL*") -> 30 | F5: ="of 30 items" -> of 30 items
B7: A. BADAS (P19) - FEASIBILITY STUDY DATA (every item is DUMMY until replaced; total investment provisional from the board deck)
B8: # | C8: Data item | D8: Definition (what the FS should provide) | E8: Unit | F8: Period | G8: Current assumption (FY2029 for annual items; phasing = total) | H8: Status | I8: Enter in (Inputs) | J8: Used in (calculation rows)
B9: B01 | C9: Commercial operation date | D9: First day of commercial operations after construction and commissioning (date). | E9: date | F9: Date | G9: =Inputs!$E$571 -> 47119 | H9: =IF(Inputs!$E$571<>'Source Data'!$E$571,"Updated - FS data entered","DUMMY - awaiting FS") -> DUMMY - awaiting FS | I9: Inputs E571 | J9: Revenue row 28
B10: B02 | C10: Design capacity | D10: Maximum annual throughput of the terminal at 100% utilisation (tons per year). | E10: tons p.a. | F10: Parameter | G10: =Inputs!$E$572 -> 1000000 | H10: =IF(Inputs!$E$572<>'Source Data'!$E$572,"Updated - FS data entered","DUMMY - awaiting FS") -> DUMMY - awaiting FS | I10: Inputs E572 | J10: Revenue row 175
B11: B03 | C11: Utilisation by year | D11: Expected throughput / design capacity for each operating year (ramp-up to steady state). | E11: % capacity | F11: Annual FY2024-36 | G11: =Inputs!M587 -> 0.55 | H11: =IF(SUMPRODUCT(--(Inputs!$H$587:$T$587<>'Source Data'!$H$587:$T$587))>0,"Updated - FS data entered","DUMMY - awaiting FS") -> DUMMY - awaiting FS | I11: Inputs H587 | J11: Revenue row 175
B12: B04 | C12: Handling tariff | D12: Tariff per ton for cargo handling (100%, before any revenue sharing), by year. | E12: IDR/t | F12: Annual FY2024-36 | G12: =Inputs!M588 -> 45000 | H12: =IF(SUMPRODUCT(--(Inputs!$H$588:$T$588<>'Source Data'!$H$588:$T$588))>0,"Updated - FS data entered","DUMMY - awaiting FS") -> DUMMY - awaiting FS | I12: Inputs H588 | J12: Revenue row 178 (+1)
B13: B05 | C13: Share of throughput stored | D13: Share of annual throughput that is stored in the terminal. | E13: % | F13: Parameter | G13: =Inputs!$E$573 -> 0.5 | H13: =IF(Inputs!$E$573<>'Source Data'!$E$573,"Updated - FS data entered","DUMMY - awaiting FS") -> DUMMY - awaiting FS | I13: Inputs E573 | J13: Revenue row 176
B14: B06 | C14: Average storage period | D14: Average months each stored ton stays in storage (drives storage revenue). | E14: months | F14: Parameter | G14: =Inputs!$E$574 -> 1.5 | H14: =IF(Inputs!$E$574<>'Source Data'!$E$574,"Updated - FS data entered","DUMMY - awaiting FS") -> DUMMY - awaiting FS | I14: Inputs E574 | J14: Revenue row 182
B15: B07 | C15: Storage tariff | D15: Tariff per ton per month of storage, by year. | E15: IDR/t/month | F15: Annual FY2024-36 | G15: =Inputs!M589 -> 12000 | H15: =IF(SUMPRODUCT(--(Inputs!$H$589:$T$589<>'Source Data'!$H$589:$T$589))>0,"Updated - FS data entered","DUMMY - awaiting FS") -> DUMMY - awaiting FS | I15: Inputs H589 | J15: Revenue row 179 (+1)
B16: B08 | C16: Share of throughput using ancillary services | D16: Share of throughput bagged / weighed (ancillary services). | E16: % | F16: Parameter | G16: =Inputs!$E$575 -> 0.3 | H16: =IF(Inputs!$E$575<>'Source Data'!$E$575,"Updated - FS data entered","DUMMY - awaiting FS") -> DUMMY - awaiting FS | I16: Inputs E575 | J16: Revenue row 177
B17: B09 | C17: Ancillary services tariff | D17: Tariff per ton for bagging / weighing, by year. | E17: IDR/t | F17: Annual FY2024-36 | G17: =Inputs!M590 -> 9000 | H17: =IF(SUMPRODUCT(--(Inputs!$H$590:$T$590<>'Source Data'!$H$590:$T$590))>0,"Updated - FS data entered","DUMMY - awaiting FS") -> DUMMY - awaiting FS | I17: Inputs H590 | J17: Revenue row 180 (+1)
B18: B10 | C18: FSL revenue share | D18: Share of gross Badas revenue received by FSL under the port / concession arrangement. | E18: % | F18: Parameter | G18: =Inputs!$E$570 -> 1 | H18: =IF(Inputs!$E$570<>'Source Data'!$E$570,"Updated - FS data entered","DUMMY - awaiting FS") -> DUMMY - awaiting FS | I18: Inputs E570 | J18: Revenue row 185
B19: B11 | C19: Concession / port fee | D19: Fee paid to the port owner or concession grantor as % of revenue, by year. | E19: % revenue | F19: Annual FY2024-36 | G19: =Inputs!M597 -> 0.05 | H19: =IF(SUMPRODUCT(--(Inputs!$H$597:$T$597<>'Source Data'!$H$597:$T$597))>0,"Updated - FS data entered","DUMMY - awaiting FS") -> DUMMY - awaiting FS | I19: Inputs H597 | J19: Costs row 205
B20: B12 | C20: Variable operating cost | D20: Cost per ton handled: fuel, power, casual labour, consumables, by year. | E20: IDR/t | F20: Annual FY2024-36 | G20: =Inputs!M591 -> 8500 | H20: =IF(SUMPRODUCT(--(Inputs!$H$591:$T$591<>'Source Data'!$H$591:$T$591))>0,"Updated - FS data entered","DUMMY - awaiting FS") -> DUMMY - awaiting FS | I20: Inputs H591 | J20: Costs row 201
B21: B13 | C21: Permanent headcount | D21: Number of permanent staff by year (staffing plan). | E21: persons | F21: Annual FY2024-36 | G21: =Inputs!M592 -> 40 | H21: =IF(SUMPRODUCT(--(Inputs!$H$592:$T$592<>'Source Data'!$H$592:$T$592))>0,"Updated - FS data entered","DUMMY - awaiting FS") -> DUMMY - awaiting FS | I21: Inputs H592 | J21: Costs row 202
B22: B14 | C22: Staff cost per head | D22: Average annual salary and benefits per permanent employee (IDR mn), by year. | E22: IDR mn p.a. | F22: Annual FY2024-36 | G22: =Inputs!M593 -> 150 | H22: =IF(SUMPRODUCT(--(Inputs!$H$593:$T$593<>'Source Data'!$H$593:$T$593))>0,"Updated - FS data entered","DUMMY - awaiting FS") -> DUMMY - awaiting FS | I22: Inputs H593 | J22: Costs row 202
B23: B15 | C23: Other fixed operating costs | D23: G&A, security, utilities and other fixed costs per year (IDR bn). | E23: IDR bn p.a. | F23: Annual FY2024-36 | G23: =Inputs!M594 -> 2.5 | H23: =IF(SUMPRODUCT(--(Inputs!$H$594:$T$594<>'Source Data'!$H$594:$T$594))>0,"Updated - FS data entered","DUMMY - awaiting FS") -> DUMMY - awaiting FS | I23: Inputs H594 | J23: Costs row 207
B24: B16 | C24: Maintenance cost | D24: Annual maintenance as % of total investment, by year. | E24: % of capex p.a. | F24: Annual FY2024-36 | G24: =Inputs!M595 -> 0.015 | H24: =IF(SUMPRODUCT(--(Inputs!$H$595:$T$595<>'Source Data'!$H$595:$T$595))>0,"Updated - FS data entered","DUMMY - awaiting FS") -> DUMMY - awaiting FS | I24: Inputs H595 | J24: Costs row 203
B25: B17 | C25: Insurance cost | D25: Annual insurance premium as % of total investment, by year. | E25: % of capex p.a. | F25: Annual FY2024-36 | G25: =Inputs!M596 -> 0.005 | H25: =IF(SUMPRODUCT(--(Inputs!$H$596:$T$596<>'Source Data'!$H$596:$T$596))>0,"Updated - FS data entered","DUMMY - awaiting FS") -> DUMMY - awaiting FS | I25: Inputs H596 | J25: Costs row 204
B26: B18 | C26: Pre-operating costs | D26: Recruitment, training and commissioning costs expensed before operations start (IDR bn). | E26: IDR bn | F26: Parameter | G26: =Inputs!$E$576 -> 1.5 | H26: =IF(Inputs!$E$576<>'Source Data'!$E$576,"Updated - FS data entered","DUMMY - awaiting FS") -> DUMMY - awaiting FS | I26: Inputs E576 | J26: Costs row 208
B27: B19 | C27: Total project investment | D27: Total capex budget incl. contingency (USD mn); provisional 10.0 from the board deck Stage 2. | E27: USD mn | F27: Parameter | G27: =Inputs!$E$577 -> 10 | H27: =IF(Inputs!$E$577<>'Source Data'!$E$577,"Updated - FS data entered","PROVISIONAL (board deck)") -> PROVISIONAL (board deck) | I27: Inputs E577 | J27: Capex row 27 (+1)
B28: B20 | C28: Capex phasing | D28: Share of the total investment spent in each year of construction (must add to 100%). | E28: % of total | F28: Annual FY2024-36 | G28: =SUM(Inputs!$H$578:$T$578) -> 1 | H28: =IF(SUMPRODUCT(--(Inputs!$H$578:$T$578<>'Source Data'!$H$578:$T$578))>0,"Updated - FS data entered","DUMMY - awaiting FS") -> DUMMY - awaiting FS | I28: Inputs H578 | J28: Capex row 27
B29: B21 | C29: Building / civil works share | D29: Share of capex in buildings and civil works (balance = equipment), for depreciation. | E29: % | F29: Parameter | G29: =Inputs!$E$579 -> 0.6 | H29: =IF(Inputs!$E$579<>'Source Data'!$E$579,"Updated - FS data entered","DUMMY - awaiting FS") -> DUMMY - awaiting FS | I29: Inputs E579 | J29: Capex row 170
B30: B22 | C30: Useful life - buildings / civil works | D30: Depreciation life of buildings and civil works (years). | E30: years | F30: Parameter | G30: =Inputs!$E$580 -> 20 | H30: =IF(Inputs!$E$580<>'Source Data'!$E$580,"Updated - FS data entered","DUMMY - awaiting FS") -> DUMMY - awaiting FS | I30: Inputs E580 | J30: Capex row 170
B31: B23 | C31: Useful life - equipment | D31: Depreciation life of equipment (years). | E31: years | F31: Parameter | G31: =Inputs!$E$581 -> 10 | H31: =IF(Inputs!$E$581<>'Source Data'!$E$581,"Updated - FS data entered","DUMMY - awaiting FS") -> DUMMY - awaiting FS | I31: Inputs E581 | J31: Capex row 170
B32: B24 | C32: Receivable days | D32: Average collection period on revenue (days). | E32: days | F32: Parameter | G32: =Inputs!$E$582 -> 45 | H32: =IF(Inputs!$E$582<>'Source Data'!$E$582,"Updated - FS data entered","DUMMY - awaiting FS") -> DUMMY - awaiting FS | I32: Inputs E582 | J32: Work. cap. row 106
B33: B25 | C33: Payable days | D33: Average payment period on cost of sales (days). | E33: days | F33: Parameter | G33: =Inputs!$E$583 -> 30 | H33: =IF(Inputs!$E$583<>'Source Data'!$E$583,"Updated - FS data entered","DUMMY - awaiting FS") -> DUMMY - awaiting FS | I33: Inputs E583 | J33: Work. cap. row 107
B34: B26 | C34: Project debt share | D34: Share of capex financed by Badas project debt (financing plan). | E34: % | F34: Parameter | G34: =Inputs!$E$584 -> 0.5 | H34: =IF(Inputs!$E$584<>'Source Data'!$E$584,"Updated - FS data entered","DUMMY - awaiting FS") -> DUMMY - awaiting FS | I34: Inputs E584 | J34: Financing row 48
B35: B27 | C35: Project debt interest rate | D35: All-in interest rate on the project debt, by year. | E35: % p.a. | F35: Annual FY2024-36 | G35: =Inputs!M598 -> 0.105 | H35: =IF(SUMPRODUCT(--(Inputs!$H$598:$T$598<>'Source Data'!$H$598:$T$598))>0,"Updated - FS data entered","DUMMY - awaiting FS") -> DUMMY - awaiting FS | I35: Inputs H598 | J35: Financing row 51
B36: B28 | C36: Project debt tenor | D36: Tenor of each drawdown incl. grace (years). | E36: years | F36: Parameter | G36: =Inputs!$E$585 -> 7 | H36: =IF(Inputs!$E$585<>'Source Data'!$E$585,"Updated - FS data entered","DUMMY - awaiting FS") -> DUMMY - awaiting FS | I36: Inputs E585 | J36: Financing row 49
B37: B29 | C37: Project debt grace period | D37: Years before principal repayments start. | E37: years | F37: Parameter | G37: =Inputs!$E$586 -> 2 | H37: =IF(Inputs!$E$586<>'Source Data'!$E$586,"Updated - FS data entered","DUMMY - awaiting FS") -> DUMMY - awaiting FS | I37: Inputs E586 | J37: Financing row 49
B38: B30 | C38: FSL ownership of the Badas entity | D38: FSL economic interest in the project company (below 100% creates a minority interest). | E38: % | F38: Parameter | G38: =Inputs!$E$569 -> 1 | H38: =IF(Inputs!$E$569<>'Source Data'!$E$569,"Updated - FS data entered","DUMMY - awaiting FS") -> DUMMY - awaiting FS | I38: Inputs E569 | J38: Out: With BUMN row 235
C40: Controls (not FS data): valuation inclusion = Inputs section 2 (register switch P19, OFF as delivered); funding inclusion = Inputs section 13 (bd.fund, ON). Corporate tax rate, FX, WACC and levers are shared with the other projects.
B42: B. FUNDING-ONLY PROJECTS (F01-F05) - capex and phasing only (no FS; never valued)
B43: # | C43: Project | D43: Data needed | E43: Unit | F43: Period | G43: Current | H43: Status | I43: Enter in (Inputs) | J43: Used in
B44: F01 | C44: ="F01 "&IF(LEN(Inputs!$E$711&"")=0,"(blank)",Inputs!$E$711) -> F01 (blank) | D44: Name | E44: text | F44: Parameter | G44: =IF(LEN(Inputs!$E$711&"")=0,"(blank)",Inputs!$E$711) -> (blank) | H44: =IF(LEN(Inputs!$E$711&"")=0,"Blank - optional","Entered") -> Blank - optional | I44: Inputs E711 | J44: Capex row 341
...

Sheet Revenue Calculation
B1: REVENUE CALCULATION - volume x tariff for every business and project (operational drivers visible; v29 methods)
B2: Volume drivers -> volume -> tariff (x tariff lever) -> revenue, each year from its own annual input. P12-P14 are calculated on BUMN Synergy Calculation and summarised here. Badas (P19): section E, DUMMY inputs. Model Flow explains the chain.
B3: Go to sheet: | C3: Model Flow | D3: Inputs | E3: FS Request | F3: [Revenue] | G3: Costs | H3: BUMN Synergy | I3: Capex | J3: Work. cap. | K3: Financing | L3: Funding | M3: Out: w/o BUMN | N3: Out: With BUMN | O3: Val: w/o BUMN | P3: Val: With BUMN | Q3: Proj. CF | R3: Proj. Summary | S3: Checks | T3: Source Data
G4: Dec-23 | H4: FY | I4: FY | J4: FY | K4: FY | L4: FY | M4: FY | N4: FY | O4: FY | P4: FY | Q4: FY | R4: FY | S4: FY | T4: FY
B5: IDR bn unless stated | C5: Unit | D5: Basis | E5: Parameter | G5: 2023 | H5: 2024 | I5: 2025 | J5: 2026 | K5: 2027 | L5: 2028 | M5: 2029 | N5: 2030 | O5: 2031 | P5: 2032 | Q5: 2033 | R5: 2034 | S5: 2035 | T5: 2036 | U5: Note
B6: A. TIMELINE AND PROJECT TIMING (1 = operating in the year; commencement year = Inputs section 2; capex timing is separate - Capex & Depreciation A)
B7: Financial year (31 December year-end) | C7: year | G7: 2023 | H7: 2024 | I7: 2025 | J7: 2026 | K7: 2027 | L7: 2028 | M7: 2029 | N7: 2030 | O7: 2031 | P7: 2032 | Q7: 2033 | R7: 2034 | S7: 2035 | T7: 2036
B8: Days in year | C8: days | G8: =DATE(G7,12,31)-DATE(G7,1,1)+1 -> 365 | H8: =DATE(H7,12,31)-DATE(H7,1,1)+1 -> 366 | I8: =DATE(I7,12,31)-DATE(I7,1,1)+1 -> 365 | J8: =DATE(J7,12,31)-DATE(J7,1,1)+1 -> 365 | K8: =DATE(K7,12,31)-DATE(K7,1,1)+1 -> 365 | L8: =DATE(L7,12,31)-DATE(L7,1,1)+1 -> 366 | M8: =DATE(M7,12,31)-DATE(M7,1,1)+1 -> 365 | N8: =DATE(N7,12,31)-DATE(N7,1,1)+1 -> 365 | ... T8: =DATE(T7,12,31)-DATE(T7,1,1)+1 -> 366
D9: Start year | E9: Included | F9: Shift vs v29 (yrs)
B10: P01 Cigading Wharf 2 | C10: flag | D10: =Inputs!$G$64 -> 2025 | E10: =Inputs!$H$64 -> 1 | F10: =D10-'Source Data'!$G$64 -> 0 | G10: 0 | H10: =IF(H7>=$D$10,1,0)*Inputs!$H$64 -> 0 | I10: =IF(I7>=$D$10,1,0)*Inputs!$H$64 -> 1 | J10: =IF(J7>=$D$10,1,0)*Inputs!$H$64 -> 1 | K10: =IF(K7>=$D$10,1,0)*Inputs!$H$64 -> 1 | L10: =IF(L7>=$D$10,1,0)*Inputs!$H$64 -> 1 | M10: =IF(M7>=$D$10,1,0)*Inputs!$H$64 -> 1 | N10: =IF(N7>=$D$10,1,0)*Inputs!$H$64 -> 1 | O10: =IF(O7>=$D$10,1,0)*Inputs!$H$64 -> 1 | ... T10: =IF(T7>=$D$10,1,0)*Inputs!$H$64 -> 1
B11: P02 Cigading extended conveyor | C11: flag | D11: =Inputs!$G$65 -> 2025 | E11: =Inputs!$H$65 -> 1 | F11: =D11-'Source Data'!$G$65 -> 0 | G11: 0 | H11: =IF(H7>=$D$11,1,0)*Inputs!$H$65 -> 0 | I11: =IF(I7>=$D$11,1,0)*Inputs!$H$65 -> 1 | J11: =IF(J7>=$D$11,1,0)*Inputs!$H$65 -> 1 | K11: =IF(K7>=$D$11,1,0)*Inputs!$H$65 -> 1 | L11: =IF(L7>=$D$11,1,0)*Inputs!$H$65 -> 1 | M11: =IF(M7>=$D$11,1,0)*Inputs!$H$65 -> 1 | N11: =IF(N7>=$D$11,1,0)*Inputs!$H$65 -> 1 | O11: =IF(O7>=$D$11,1,0)*Inputs!$H$65 -> 1 | ... T11: =IF(T7>=$D$11,1,0)*Inputs!$H$65 -> 1
B12: P03 KBS warehouse revitalisation (FSL 49% revenue share) | C12: flag | D12: =Inputs!$G$66 -> 2027 | E12: =Inputs!$H$66 -> 1 | F12: =D12-'Source Data'!$G$66 -> 0 | G12: 0 | H12: =IF(H7>=$D$12,1,0)*Inputs!$H$66 -> 0 | I12: =IF(I7>=$D$12,1,0)*Inputs!$H$66 -> 0 | J12: =IF(J7>=$D$12,1,0)*Inputs!$H$66 -> 0 | K12: =IF(K7>=$D$12,1,0)*Inputs!$H$66 -> 1 | L12: =IF(L7>=$D$12,1,0)*Inputs!$H$66 -> 1 | M12: =IF(M7>=$D$12,1,0)*Inputs!$H$66 -> 1 | N12: =IF(N7>=$D$12,1,0)*Inputs!$H$66 -> 1 | O12: =IF(O7>=$D$12,1,0)*Inputs!$H$66 -> 1 | ... T12: =IF(T7>=$D$12,1,0)*Inputs!$H$66 -> 1
B13: P04 Teluk Lamong silo | C13: flag | D13: =Inputs!$G$67 -> 2027 | E13: =Inputs!$H$67 -> 1 | F13: =D13-'Source Data'!$G$67 -> 0 | G13: 0 | H13: =IF(H7>=$D$13,1,0)*Inputs!$H$67 -> 0 | I13: =IF(I7>=$D$13,1,0)*Inputs!$H$67 -> 0 | J13: =IF(J7>=$D$13,1,0)*Inputs!$H$67 -> 0 | K13: =IF(K7>=$D$13,1,0)*Inputs!$H$67 -> 1 | L13: =IF(L7>=$D$13,1,0)*Inputs!$H$67 -> 1 | M13: =IF(M7>=$D$13,1,0)*Inputs!$H$67 -> 1 | N13: =IF(N7>=$D$13,1,0)*Inputs!$H$67 -> 1 | O13: =IF(O7>=$D$13,1,0)*Inputs!$H$67 -> 1 | ... T13: =IF(T7>=$D$13,1,0)*Inputs!$H$67 -> 1
B14: P05 Dumai bagging & weighbridge | C14: flag | D14: =Inputs!$G$68 -> 2026 | E14: =Inputs!$H$68 -> 1 | F14: =D14-'Source Data'!$G$68 -> 0 | G14: 0 | H14: =IF(H7>=$D$14,1,0)*Inputs!$H$68 -> 0 | I14: =IF(I7>=$D$14,1,0)*Inputs!$H$68 -> 0 | J14: =IF(J7>=$D$14,1,0)*Inputs!$H$68 -> 1 | K14: =IF(K7>=$D$14,1,0)*Inputs!$H$68 -> 1 | L14: =IF(L7>=$D$14,1,0)*Inputs!$H$68 -> 1 | M14: =IF(M7>=$D$14,1,0)*Inputs!$H$68 -> 1 | N14: =IF(N7>=$D$14,1,0)*Inputs!$H$68 -> 1 | O14: =IF(O7>=$D$14,1,0)*Inputs!$H$68 -> 1 | ... T14: =IF(T7>=$D$14,1,0)*Inputs!$H$68 -> 1
B15: P06 Ciwandan expansion (FSL 52% tariff share) | C15: flag | D15: =Inputs!$G$69 -> 2028 | E15: =Inputs!$H$69 -> 1 | F15: =D15-'Source Data'!$G$69 -> 0 | G15: 0 | H15: =IF(H7>=$D$15,1,0)*Inputs!$H$69 -> 0 | I15: =IF(I7>=$D$15,1,0)*Inputs!$H$69 -> 0 | J15: =IF(J7>=$D$15,1,0)*Inputs!$H$69 -> 0 | K15: =IF(K7>=$D$15,1,0)*Inputs!$H$69 -> 0 | L15: =IF(L7>=$D$15,1,0)*Inputs!$H$69 -> 1 | M15: =IF(M7>=$D$15,1,0)*Inputs!$H$69 -> 1 | N15: =IF(N7>=$D$15,1,0)*Inputs!$H$69 -> 1 | O15: =IF(O7>=$D$15,1,0)*Inputs!$H$69 -> 1 | ... T15: =IF(T7>=$D$15,1,0)*Inputs!$H$69 -> 1
B16: P07 Belawan expansion (additional volume) | C16: flag | D16: =Inputs!$G$70 -> 2026 | E16: =Inputs!$H$70 -> 1 | F16: =D16-'Source Data'!$G$70 -> 0 | G16: 0 | H16: =IF(H7>=$D$16,1,0)*Inputs!$H$70 -> 0 | I16: =IF(I7>=$D$16,1,0)*Inputs!$H$70 -> 0 | J16: =IF(J7>=$D$16,1,0)*Inputs!$H$70 -> 1 | K16: =IF(K7>=$D$16,1,0)*Inputs!$H$70 -> 1 | L16: =IF(L7>=$D$16,1,0)*Inputs!$H$70 -> 1 | M16: =IF(M7>=$D$16,1,0)*Inputs!$H$70 -> 1 | N16: =IF(N7>=$D$16,1,0)*Inputs!$H$70 -> 1 | O16: =IF(O7>=$D$16,1,0)*Inputs!$H$70 -> 1 | ... T16: =IF(T7>=$D$16,1,0)*Inputs!$H$70 -> 1
B17: P08 DMS trucking fee - Teluk Lamong | C17: flag | D17: =Inputs!$G$71 -> 2027 | E17: =Inputs!$H$71 -> 1 | F17: =D17-'Source Data'!$G$71 -> 0 | G17: 0 | H17: =IF(H7>=$D$17,1,0)*Inputs!$H$71 -> 0 | I17: =IF(I7>=$D$17,1,0)*Inputs!$H$71 -> 0 | J17: =IF(J7>=$D$17,1,0)*Inputs!$H$71 -> 0 | K17: =IF(K7>=$D$17,1,0)*Inputs!$H$71 -> 1 | L17: =IF(L7>=$D$17,1,0)*Inputs!$H$71 -> 1 | M17: =IF(M7>=$D$17,1,0)*Inputs!$H$71 -> 1 | N17: =IF(N7>=$D$17,1,0)*Inputs!$H$71 -> 1 | O17: =IF(O7>=$D$17,1,0)*Inputs!$H$71 -> 1 | ... T17: =IF(T7>=$D$17,1,0)*Inputs!$H$71 -> 1
B18: P09 DMS trucking fee - Cigading | C18: flag | D18: =Inputs!$G$72 -> 2027 | E18: =Inputs!$H$72 -> 1 | F18: =D18-'Source Data'!$G$72 -> 0 | G18: 0 | H18: =IF(H7>=$D$18,1,0)*Inputs!$H$72 -> 0 | I18: =IF(I7>=$D$18,1,0)*Inputs!$H$72 -> 0 | J18: =IF(J7>=$D$18,1,0)*Inputs!$H$72 -> 0 | K18: =IF(K7>=$D$18,1,0)*Inputs!$H$72 -> 1 | L18: =IF(L7>=$D$18,1,0)*Inputs!$H$72 -> 1 | M18: =IF(M7>=$D$18,1,0)*Inputs!$H$72 -> 1 | N18: =IF(N7>=$D$18,1,0)*Inputs!$H$72 -> 1 | O18: =IF(O7>=$D$18,1,0)*Inputs!$H$72 -> 1 | ... T18: =IF(T7>=$D$18,1,0)*Inputs!$H$72 -> 1
B19: P10 DMS trucking fee - Ciwandan | C19: flag | D19: =Inputs!$G$73 -> 2028 | E19: =Inputs!$H$73 -> 1 | F19: =D19-'Source Data'!$G$73 -> 0 | G19: 0 | H19: =IF(H7>=$D$19,1,0)*Inputs!$H$73 -> 0 | I19: =IF(I7>=$D$19,1,0)*Inputs!$H$73 -> 0 | J19: =IF(J7>=$D$19,1,0)*Inputs!$H$73 -> 0 | K19: =IF(K7>=$D$19,1,0)*Inputs!$H$73 -> 0 | L19: =IF(L7>=$D$19,1,0)*Inputs!$H$73 -> 1 | M19: =IF(M7>=$D$19,1,0)*Inputs!$H$73 -> 1 | N19: =IF(N7>=$D$19,1,0)*Inputs!$H$73 -> 1 | O19: =IF(O7>=$D$19,1,0)*Inputs!$H$73 -> 1 | ... T19: =IF(T7>=$D$19,1,0)*Inputs!$H$73 -> 1
B20: P11 DMS trucking fee - Belawan | C20: flag | D20: =Inputs!$G$74 -> 2027 | E20: =Inputs!$H$74 -> 1 | F20: =D20-'Source Data'!$G$74 -> 0 | G20: 0 | H20: =IF(H7>=$D$20,1,0)*Inputs!$H$74 -> 0 | I20: =IF(I7>=$D$20,1,0)*Inputs!$H$74 -> 0 | J20: =IF(J7>=$D$20,1,0)*Inputs!$H$74 -> 0 | K20: =IF(K7>=$D$20,1,0)*Inputs!$H$74 -> 1 | L20: =IF(L7>=$D$20,1,0)*Inputs!$H$74 -> 1 | M20: =IF(M7>=$D$20,1,0)*Inputs!$H$74 -> 1 | N20: =IF(N7>=$D$20,1,0)*Inputs!$H$74 -> 1 | O20: =IF(O7>=$D$20,1,0)*Inputs!$H$74 -> 1 | ... T20: =IF(T7>=$D$20,1,0)*Inputs!$H$74 -> 1
B21: P12 BUMN synergy - Pelindo Teluk Lamong operatorship | C21: flag | D21: =Inputs!$G$75 -> 2026 | E21: =Inputs!$H$75 -> 1 | F21: =D21-'Source Data'!$G$75 -> 0 | G21: 0 | H21: =IF(H7>=$D$21,1,0)*Inputs!$H$75 -> 0 | I21: =IF(I7>=$D$21,1,0)*Inputs!$H$75 -> 0 | J21: =IF(J7>=$D$21,1,0)*Inputs!$H$75 -> 1 | K21: =IF(K7>=$D$21,1,0)*Inputs!$H$75 -> 1 | L21: =IF(L7>=$D$21,1,0)*Inputs!$H$75 -> 1 | M21: =IF(M7>=$D$21,1,0)*Inputs!$H$75 -> 1 | N21: =IF(N7>=$D$21,1,0)*Inputs!$H$75 -> 1 | O21: =IF(O7>=$D$21,1,0)*Inputs!$H$75 -> 1 | ... T21: =IF(T7>=$D$21,1,0)*Inputs!$H$75 -> 1
B22: P13 BUMN synergy - KBS Cigading operatorship | C22: flag | D22: =Inputs!$G$76 -> 2026 | E22: =Inputs!$H$76 -> 1 | F22: =D22-'Source Data'!$G$76 -> 0 | G22: 0 | H22: =IF(H7>=$D$22,1,0)*Inputs!$H$76 -> 0 | I22: =IF(I7>=$D$22,1,0)*Inputs!$H$76 -> 0 | J22: =IF(J7>=$D$22,1,0)*Inputs!$H$76 -> 1 | K22: =IF(K7>=$D$22,1,0)*Inputs!$H$76 -> 1 | L22: =IF(L7>=$D$22,1,0)*Inputs!$H$76 -> 1 | M22: =IF(M7>=$D$22,1,0)*Inputs!$H$76 -> 1 | N22: =IF(N7>=$D$22,1,0)*Inputs!$H$76 -> 1 | O22: =IF(O7>=$D$22,1,0)*Inputs!$H$76 -> 1 | ... T22: =IF(T7>=$D$22,1,0)*Inputs!$H$76 -> 1
B23: P14 BUMN synergy - Pelindo Belawan operatorship | C23: flag | D23: =Inputs!$G$77 -> 2026 | E23: =Inputs!$H$77 -> 1 | F23: =D23-'Source Data'!$G$77 -> 0 | G23: 0 | H23: =IF(H7>=$D$23,1,0)*Inputs!$H$77 -> 0 | I23: =IF(I7>=$D$23,1,0)*Inputs!$H$77 -> 0 | J23: =IF(J7>=$D$23,1,0)*Inputs!$H$77 -> 1 | K23: =IF(K7>=$D$23,1,0)*Inputs!$H$77 -> 1 | L23: =IF(L7>=$D$23,1,0)*Inputs!$H$77 -> 1 | M23: =IF(M7>=$D$23,1,0)*Inputs!$H$77 -> 1 | N23: =IF(N7>=$D$23,1,0)*Inputs!$H$77 -> 1 | O23: =IF(O7>=$D$23,1,0)*Inputs!$H$77 -> 1 | ... T23: =IF(T7>=$D$23,1,0)*Inputs!$H$77 -> 1
B24: P15 TBM (land lease, warehousing, cargo handling) | C24: flag | D24: =Inputs!$G$78 -> 2029 | E24: =Inputs!$H$78 -> 0 | F24: =D24-'Source Data'!$G$78 -> 0 | G24: 0 | H24: =IF(H7>=$D$24,1,0)*Inputs!$H$78 -> 0 | I24: =IF(I7>=$D$24,1,0)*Inputs!$H$78 -> 0 | J24: =IF(J7>=$D$24,1,0)*Inputs!$H$78 -> 0 | K24: =IF(K7>=$D$24,1,0)*Inputs!$H$78 -> 0 | L24: =IF(L7>=$D$24,1,0)*Inputs!$H$78 -> 0 | M24: =IF(M7>=$D$24,1,0)*Inputs!$H$78 -> 0 | N24: =IF(N7>=$D$24,1,0)*Inputs!$H$78 -> 0 | O24: =IF(O7>=$D$24,1,0)*Inputs!$H$78 -> 0 | ... T24: =IF(T7>=$D$24,1,0)*Inputs!$H$78 -> 0
B25: ="P16 "&Inputs!$E$605&" - operating fraction of the year (part year from the commencement date)" -> P16 Lampung - operating fraction of the year (part year from the commencement date) | C25: share | E25: =Inputs!$H$79 -> 0 | G25: 0 | H25: =IF(Inputs!$H$79=1,MAX(0,MIN(1,(DATE(H7,12,31)-MAX(DATE(H7,1,1),N(Inputs!$E$607))+1)/H8)),0) -> 0 | I25: =IF(Inputs!$H$79=1,MAX(0,MIN(1,(DATE(I7,12,31)-MAX(DATE(I7,1,1),N(Inputs!$E$607))+1)/I8)),0) -> 0 | J25: =IF(Inputs!$H$79=1,MAX(0,MIN(1,(DATE(J7,12,31)-MAX(DATE(J7,1,1),N(Inputs!$E$607))+1)/J8)),0) -> 0 | K25: =IF(Inputs!$H$79=1,MAX(0,MIN(1,(DATE(K7,12,31)-MAX(DATE(K7,1,1),N(Inputs!$E$607))+1)/K8)),0) -> 0 | L25: =IF(Inputs!$H$79=1,MAX(0,MIN(1,(DATE(L7,12,31)-MAX(DATE(L7,1,1),N(Inputs!$E$607))+1)/L8)),0) -> 0 | M25: =IF(Inputs!$H$79=1,MAX(0,MIN(1,(DATE(M7,12,31)-MAX(DATE(M7,1,1),N(Inputs!$E$607))+1)/M8)),0) -> 0 | N25: =IF(Inputs!$H$79=1,MAX(0,MIN(1,(DATE(N7,12,31)-MAX(DATE(N7,1,1),N(Inputs!$E$607))+1)/N8)),0) -> 0 | O25: =IF(Inputs!$H$79=1,MAX(0,MIN(1,(DATE(O7,12,31)-MAX(DATE(O7,1,1),N(Inputs!$E$607))+1)/O8)),0) -> 0 | ... T25: =IF(Inputs!$H$79=1,MAX(0,MIN(1,(DATE(T7,12,31)-MAX(DATE(T7,1,1),N(Inputs!$E$607))+1)/T8)),0) -> 0
B26: ="P17 "&Inputs!$E$639&" - operating fraction of the year (part year from the commencement date)" -> P17 Pipeline Project 2 - operating fraction of the year (part year from the commencement date) | C26: share | E26: =Inputs!$H$80 -> 0 | G26: 0 | H26: =IF(Inputs!$H$80=1,MAX(0,MIN(1,(DATE(H7,12,31)-MAX(DATE(H7,1,1),N(Inputs!$E$641))+1)/H8)),0) -> 0 | I26: =IF(Inputs!$H$80=1,MAX(0,MIN(1,(DATE(I7,12,31)-MAX(DATE(I7,1,1),N(Inputs!$E$641))+1)/I8)),0) -> 0 | J26: =IF(Inputs!$H$80=1,MAX(0,MIN(1,(DATE(J7,12,31)-MAX(DATE(J7,1,1),N(Inputs!$E$641))+1)/J8)),0) -> 0 | K26: =IF(Inputs!$H$80=1,MAX(0,MIN(1,(DATE(K7,12,31)-MAX(DATE(K7,1,1),N(Inputs!$E$641))+1)/K8)),0) -> 0 | L26: =IF(Inputs!$H$80=1,MAX(0,MIN(1,(DATE(L7,12,31)-MAX(DATE(L7,1,1),N(Inputs!$E$641))+1)/L8)),0) -> 0 | M26: =IF(Inputs!$H$80=1,MAX(0,MIN(1,(DATE(M7,12,31)-MAX(DATE(M7,1,1),N(Inputs!$E$641))+1)/M8)),0) -> 0 | N26: =IF(Inputs!$H$80=1,MAX(0,MIN(1,(DATE(N7,12,31)-MAX(DATE(N7,1,1),N(Inputs!$E$641))+1)/N8)),0) -> 0 | O26: =IF(Inputs!$H$80=1,MAX(0,MIN(1,(DATE(O7,12,31)-MAX(DATE(O7,1,1),N(Inputs!$E$641))+1)/O8)),0) -> 0 | ... T26: =IF(Inputs!$H$80=1,MAX(0,MIN(1,(DATE(T7,12,31)-MAX(DATE(T7,1,1),N(Inputs!$E$641))+1)/T8)),0) -> 0
B27: ="P18 "&Inputs!$E$673&" - operating fraction of the year (part year from the commencement date)" -> P18 Pipeline Project 3 - operating fraction of the year (part year from the commencement date) | C27: share | E27: =Inputs!$H$81 -> 0 | G27: 0 | H27: =IF(Inputs!$H$81=1,MAX(0,MIN(1,(DATE(H7,12,31)-MAX(DATE(H7,1,1),N(Inputs!$E$675))+1)/H8)),0) -> 0 | I27: =IF(Inputs!$H$81=1,MAX(0,MIN(1,(DATE(I7,12,31)-MAX(DATE(I7,1,1),N(Inputs!$E$675))+1)/I8)),0) -> 0 | J27: =IF(Inputs!$H$81=1,MAX(0,MIN(1,(DATE(J7,12,31)-MAX(DATE(J7,1,1),N(Inputs!$E$675))+1)/J8)),0) -> 0 | K27: =IF(Inputs!$H$81=1,MAX(0,MIN(1,(DATE(K7,12,31)-MAX(DATE(K7,1,1),N(Inputs!$E$675))+1)/K8)),0) -> 0 | L27: =IF(Inputs!$H$81=1,MAX(0,MIN(1,(DATE(L7,12,31)-MAX(DATE(L7,1,1),N(Inputs!$E$675))+1)/L8)),0) -> 0 | M27: =IF(Inputs!$H$81=1,MAX(0,MIN(1,(DATE(M7,12,31)-MAX(DATE(M7,1,1),N(Inputs!$E$675))+1)/M8)),0) -> 0 | N27: =IF(Inputs!$H$81=1,MAX(0,MIN(1,(DATE(N7,12,31)-MAX(DATE(N7,1,1),N(Inputs!$E$675))+1)/N8)),0) -> 0 | O27: =IF(Inputs!$H$81=1,MAX(0,MIN(1,(DATE(O7,12,31)-MAX(DATE(O7,1,1),N(Inputs!$E$675))+1)/O8)),0) -> 0 | ... T27: =IF(Inputs!$H$81=1,MAX(0,MIN(1,(DATE(T7,12,31)-MAX(DATE(T7,1,1),N(Inputs!$E$675))+1)/T8)),0) -> 0
B28: P19 Badas - operating fraction of the year from the commercial operation date (illustrative, always calculated) | C28: share | D28: =YEAR(Inputs!$E$571) -> 2029 | G28: 0 | H28: =MAX(0,MIN(1,(DATE(H7,12,31)-MAX(DATE(H7,1,1),Inputs!$E$571)+1)/H8)) -> 0 | I28: =MAX(0,MIN(1,(DATE(I7,12,31)-MAX(DATE(I7,1,1),Inputs!$E$571)+1)/I8)) -> 0 | J28: =MAX(0,MIN(1,(DATE(J7,12,31)-MAX(DATE(J7,1,1),Inputs!$E$571)+1)/J8)) -> 0 | K28: =MAX(0,MIN(1,(DATE(K7,12,31)-MAX(DATE(K7,1,1),Inputs!$E$571)+1)/K8)) -> 0 | L28: =MAX(0,MIN(1,(DATE(L7,12,31)-MAX(DATE(L7,1,1),Inputs!$E$571)+1)/L8)) -> 0 | M28: =MAX(0,MIN(1,(DATE(M7,12,31)-MAX(DATE(M7,1,1),Inputs!$E$571)+1)/M8)) -> 1 | N28: =MAX(0,MIN(1,(DATE(N7,12,31)-MAX(DATE(N7,1,1),Inputs!$E$571)+1)/N8)) -> 1 | O28: =MAX(0,MIN(1,(DATE(O7,12,31)-MAX(DATE(O7,1,1),Inputs!$E$571)+1)/O8)) -> 1 | ... T28: =MAX(0,MIN(1,(DATE(T7,12,31)-MAX(DATE(T7,1,1),Inputs!$E$571)+1)/T8)) -> 1
B29: P19 Badas - operating fraction in the FSL statements = illustrative x valuation inclusion | C29: share | E29: =Inputs!$H$82 -> 1 | G29: 0 | H29: =H28*Inputs!$H$82 -> 0 | I29: =I28*Inputs!$H$82 -> 0 | J29: =J28*Inputs!$H$82 -> 0 | K29: =K28*Inputs!$H$82 -> 0 | L29: =L28*Inputs!$H$82 -> 0 | M29: =M28*Inputs!$H$82 -> 1 | N29: =N28*Inputs!$H$82 -> 1 | O29: =O28*Inputs!$H$82 -> 1 | ... T29: =T28*Inputs!$H$82 -> 1
B30: P01-P02 commence in FY2025 under v29 (construction since before FY2024). Changing a commencement year (Inputs section 2) moves the operating flags and the v29 calendar schedules of that project (column F); it does not move capex, which follows the spending % rows.
B32: B. EXISTING BUSINESSES (E1-E4)
B33: E1 Teluk Lamong - NPLOG cargodoring & delivery
B34: Meals volume index (FY2023 = 1; x (1 + growth of the year)) | C34: index | D34: Inputs 4 growth | G34: 1 | H34: =G34*(1+Inputs!H108) -> 1 | I34: =H34*(1+Inputs!I108) -> 1.03 | J34: =I34*(1+Inputs!J108) -> 1.0609 | K34: =J34*(1+Inputs!K108) -> 1.092727 | L34: =K34*(1+Inputs!L108) -> 1.1255088 | M34: =L34*(1+Inputs!M108) -> 1.1592741 | N34: =M34*(1+Inputs!N108) -> 1.1940523 | O34: =N34*(1+Inputs!O108) -> 1.2298739 | ... T34: =S34*(1+Inputs!T108) -> 1.4257609
B35: Grains volume index (FY2023 = 1) | C35: index | D35: Inputs 4 growth | G35: 1 | H35: =G35*(1+Inputs!H109) -> 1 | I35: =H35*(1+Inputs!I109) -> 1.03 | J35: =I35*(1+Inputs!J109) -> 1.0609 | K35: =J35*(1+Inputs!K109) -> 1.092727 | L35: =K35*(1+Inputs!L109) -> 1.1255088 | M35: =L35*(1+Inputs!M109) -> 1.1592741 | N35: =M35*(1+Inputs!N109) -> 1.1940523 | O35: =N35*(1+Inputs!O109) -> 1.2298739 | ... T35: =S35*(1+Inputs!T109) -> 1.4257609
B36: Meals throughput = FY2023 base x FY2024 reset x index x volume lever | C36: tons | H36: =Inputs!$E$103*Inputs!$E$104*H34*Inputs!$E$52 -> 2063651.1 | I36: =Inputs!$E$103*Inputs!$E$104*I34*Inputs!$E$52 -> 2125560.6 | J36: =Inputs!$E$103*Inputs!$E$104*J34*Inputs!$E$52 -> 2189327.4 | K36: =Inputs!$E$103*Inputs!$E$104*K34*Inputs!$E$52 -> 2255007.2 | L36: =Inputs!$E$103*Inputs!$E$104*L34*Inputs!$E$52 -> 2322657.5 | M36: =Inputs!$E$103*Inputs!$E$104*M34*Inputs!$E$52 -> 2392337.2 | N36: =Inputs!$E$103*Inputs!$E$104*N34*Inputs!$E$52 -> 2464107.3 | O36: =Inputs!$E$103*Inputs!$E$104*O34*Inputs!$E$52 -> 2538030.5 | ... T36: =Inputs!$E$103*Inputs!$E$104*T34*Inputs!$E$52 -> 2942273
B37: Grains throughput = FY2023 base x FY2024 reset x index x volume lever | C37: tons | H37: =Inputs!$E$105*Inputs!$E$106*H35*Inputs!$E$52 -> 1602574.2 | I37: =Inputs!$E$105*Inputs!$E$106*I35*Inputs!$E$52 -> 1650651.4 | J37: =Inputs!$E$105*Inputs!$E$106*J35*Inputs!$E$52 -> 1700171 | K37: =Inputs!$E$105*Inputs!$E$106*K35*Inputs!$E$52 -> 1751176.1 | L37: =Inputs!$E$105*Inputs!$E$106*L35*Inputs!$E$52 -> 1803711.4 | M37: =Inputs!$E$105*Inputs!$E$106*M35*Inputs!$E$52 -> 1857822.7 | N37: =Inputs!$E$105*Inputs!$E$106*N35*Inputs!$E$52 -> 1913557.4 | O37: =Inputs!$E$105*Inputs!$E$106*O35*Inputs!$E$52 -> 1970964.1 | ... T37: =Inputs!$E$105*Inputs!$E$106*T35*Inputs!$E$52 -> 2284887.6
B38: Total throughput | C38: tons | H38: =H36+H37 -> 3666225.3 | I38: =I36+I37 -> 3776212 | J38: =J36+J37 -> 3889498.4 | K38: =K36+K37 -> 4006183.3 | L38: =L36+L37 -> 4126368.8 | M38: =M36+M37 -> 4250159.9 | N38: =N36+N37 -> 4377664.7 | O38: =O36+O37 -> 4508994.7 | ... T38: =T36+T37 -> 5227160.6
B39: Meals tariff (annual input x tariff lever) | C39: IDR/t | H39: =Inputs!H110*Inputs!$E$53 -> 42880 | I39: =Inputs!I110*Inputs!$E$53 -> 42880 | J39: =Inputs!J110*Inputs!$E$53 -> 42880 | K39: =Inputs!K110*Inputs!$E$53 -> 42880 | L39: =Inputs!L110*Inputs!$E$53 -> 42880 | M39: =Inputs!M110*Inputs!$E$53 -> 44166.4 | N39: =Inputs!N110*Inputs!$E$53 -> 44166.4 | O39: =Inputs!O110*Inputs!$E$53 -> 44166.4 | ... T39: =Inputs!T110*Inputs!$E$53 -> 45491.392
B40: Grains tariff (annual input x tariff lever) | C40: IDR/t | H40: =Inputs!H111*Inputs!$E$53 -> 42400 | I40: =Inputs!I111*Inputs!$E$53 -> 42400 | J40: =Inputs!J111*Inputs!$E$53 -> 42400 | K40: =Inputs!K111*Inputs!$E$53 -> 42400 | L40: =Inputs!L111*Inputs!$E$53 -> 42400 | M40: =Inputs!M111*Inputs!$E$53 -> 43672 | N40: =Inputs!N111*Inputs!$E$53 -> 43672 | O40: =Inputs!O111*Inputs!$E$53 -> 43672 | ... T40: =Inputs!T111*Inputs!$E$53 -> 44982.16
B41: E1 Revenue = (meals volume x meals tariff + grains volume x grains tariff) / 1e9 | C41: IDR bn | H41: =(H36*H39+H37*H40)/1000000000 -> 156.4385 | I41: =(I36*I39+I37*I40)/1000000000 -> 161.13166 | J41: =(J36*J39+J37*J40)/1000000000 -> 165.96561 | K41: =(K36*K39+K37*K40)/1000000000 -> 170.94458 | L41: =(L36*L39+L37*L40)/1000000000 -> 176.07291 | M41: =(M36*M39+M37*M40)/1000000000 -> 186.79576 | N41: =(N36*N39+N37*N40)/1000000000 -> 192.39963 | O41: =(O36*O39+O37*O40)/1000000000 -> 198.17162 | ... T41: =(T36*T39+T37*T40)/1000000000 -> 236.62727
...

Sheet Cost Calculation
B1: COST CALCULATION - cost of sales, operating expenses and EBITDA by business and project (cost drivers visible; v29 methods)
B2: Existing businesses: v29 cost lines (fixed amounts, unit costs per ton, ratios). Projects: v29 cost ratios and shared unit costs. Costs are positive here and deducted in the outputs.
B3: Go to sheet: | C3: Model Flow | D3: Inputs | E3: FS Request | F3: Revenue | G3: [Costs] | H3: BUMN Synergy | I3: Capex | J3: Work. cap. | K3: Financing | L3: Funding | M3: Out: w/o BUMN | N3: Out: With BUMN | O3: Val: w/o BUMN | P3: Val: With BUMN | Q3: Proj. CF | R3: Proj. Summary | S3: Checks | T3: Source Data
G4: Dec-23 | H4: FY | I4: FY | J4: FY | K4: FY | L4: FY | M4: FY | N4: FY | O4: FY | P4: FY | Q4: FY | R4: FY | S4: FY | T4: FY
B5: IDR bn unless stated | C5: Unit | D5: Basis | E5: Parameter | G5: 2023 | H5: 2024 | I5: 2025 | J5: 2026 | K5: 2027 | L5: 2028 | M5: 2029 | N5: 2030 | O5: 2031 | P5: 2032 | Q5: 2033 | R5: 2034 | S5: 2035 | T5: 2036 | U5: Note
B6: A. EXISTING BUSINESSES (E1-E4) - cost lines, cost of sales, operating expenses, EBITDA
B7: E1 Teluk Lamong (NPLOG)
B8: E1 cost lines (before the cost lever; 2023 column = FY2023 base x v29 uplift; each later year = prior year x (1 + that year's growth))
B9: Employee cost (payroll) | C9: IDR bn | D9: COGS fixed | G9: =Inputs!$E$317*Inputs!$F$317 -> 12.869296 | H9: =G9*(1+Inputs!H317) -> 13.319721 | I9: =H9*(1+Inputs!I317) -> 13.785911 | J9: =I9*(1+Inputs!J317) -> 14.268418 | K9: =J9*(1+Inputs!K317) -> 14.767813 | L9: =K9*(1+Inputs!L317) -> 15.284686 | M9: =L9*(1+Inputs!M317) -> 15.81965 | N9: =M9*(1+Inputs!N317) -> 16.373338 | O9: =N9*(1+Inputs!O317) -> 16.946405 | ... T9: =S9*(1+Inputs!T317) -> 20.127013
B10: Electricity - unit cost | C10: IDR/t | D10: COGS per t | G10: =Inputs!$E$318*Inputs!$F$318/Inputs!$E$107*1000000000 -> 1452.8478 | H10: =G10*(1+Inputs!H318) -> 1496.4333 | I10: =H10*(1+Inputs!I318) -> 1541.3263 | J10: =I10*(1+Inputs!J318) -> 1587.5661 | K10: =J10*(1+Inputs!K318) -> 1635.193 | L10: =K10*(1+Inputs!L318) -> 1684.2488 | M10: =L10*(1+Inputs!M318) -> 1734.7763 | N10: =M10*(1+Inputs!N318) -> 1786.8196 | O10: =N10*(1+Inputs!O318) -> 1840.4242 | ... T10: =S10*(1+Inputs!T318) -> 2133.556
B11: Fuel - unit cost | C11: IDR/t | D11: COGS per t | G11: =Inputs!$E$319*Inputs!$F$319/Inputs!$E$107*1000000000 -> 856.40404 | H11: =G11*(1+Inputs!H319) -> 882.09616 | I11: =H11*(1+Inputs!I319) -> 908.55904 | J11: =I11*(1+Inputs!J319) -> 935.81582 | K11: =J11*(1+Inputs!K319) -> 963.89029 | L11: =K11*(1+Inputs!L319) -> 992.807 | M11: =L11*(1+Inputs!M319) -> 1022.5912 | N11: =M11*(1+Inputs!N319) -> 1053.2689 | O11: =N11*(1+Inputs!O319) -> 1084.867 | ... T11: =S11*(1+Inputs!T319) -> 1257.6582
B12: Security | C12: IDR bn | D12: COGS fixed | G12: =Inputs!$E$320*Inputs!$F$320 -> 2.0920344 | H12: =G12*(1+Inputs!H320) -> 2.1652557 | I12: =H12*(1+Inputs!I320) -> 2.2410396 | J12: =I12*(1+Inputs!J320) -> 2.319476 | K12: =J12*(1+Inputs!K320) -> 2.4006576 | L12: =K12*(1+Inputs!L320) -> 2.4846807 | M12: =L12*(1+Inputs!M320) -> 2.5716445 | N12: =M12*(1+Inputs!N320) -> 2.661652 | O12: =N12*(1+Inputs!O320) -> 2.7548099 | ... T12: =S12*(1+Inputs!T320) -> 3.27185
B13: Repair & maintenance - unit cost | C13: IDR/t | D13: COGS per t | G13: =Inputs!$E$321*Inputs!$F$321/Inputs!$E$107*1000000000 -> 685.45176 | H13: =G13*(1+Inputs!H321) -> 706.01531 | I13: =H13*(1+Inputs!I321) -> 727.19577 | J13: =I13*(1+Inputs!J321) -> 749.01164 | K13: =J13*(1+Inputs!K321) -> 771.48199 | L13: =K13*(1+Inputs!L321) -> 794.62645 | M13: =L13*(1+Inputs!M321) -> 818.46525 | N13: =M13*(1+Inputs!N321) -> 843.0192 | O13: =N13*(1+Inputs!O321) -> 868.30978 | ... T13: =S13*(1+Inputs!T321) -> 1006.609
B14: Employee overtime - unit cost | C14: IDR/t | D14: COGS per t | G14: =Inputs!$E$322*Inputs!$F$322/Inputs!$E$107*1000000000 -> 348.14268 | H14: =G14*(1+Inputs!H322) -> 360.32768 | I14: =H14*(1+Inputs!I322) -> 372.93914 | J14: =I14*(1+Inputs!J322) -> 385.99201 | K14: =J14*(1+Inputs!K322) -> 399.50174 | L14: =K14*(1+Inputs!L322) -> 413.4843 | M14: =L14*(1+Inputs!M322) -> 427.95625 | N14: =M14*(1+Inputs!N322) -> 442.93471 | O14: =N14*(1+Inputs!O322) -> 458.43743 | ... T14: =S14*(1+Inputs!T322) -> 544.47986
B15: Labour (variable) - unit cost | C15: IDR/t | D15: COGS per t | G15: =Inputs!$E$323*Inputs!$F$323/Inputs!$E$107*1000000000 -> 180.19111 | H15: =G15*(1+Inputs!H323) -> 186.4978 | I15: =H15*(1+Inputs!I323) -> 193.02522 | J15: =I15*(1+Inputs!J323) -> 199.7811 | K15: =J15*(1+Inputs!K323) -> 206.77344 | L15: =K15*(1+Inputs!L323) -> 214.01051 | M15: =L15*(1+Inputs!M323) -> 221.50088 | N15: =M15*(1+Inputs!N323) -> 229.25341 | O15: =N15*(1+Inputs!O323) -> 237.27728 | ... T15: =S15*(1+Inputs!T323) -> 281.81098
B16: Other operating expense - unit cost | C16: IDR/t | D16: COGS per t | G16: =Inputs!$E$324*Inputs!$F$324/Inputs!$E$107*1000000000 -> 66.750238 | H16: =G16*(1+Inputs!H324) -> 68.752745 | I16: =H16*(1+Inputs!I324) -> 70.815327 | J16: =I16*(1+Inputs!J324) -> 72.939787 | K16: =J16*(1+Inputs!K324) -> 75.127981 | L16: =K16*(1+Inputs!L324) -> 77.38182 | M16: =L16*(1+Inputs!M324) -> 79.703275 | N16: =M16*(1+Inputs!N324) -> 82.094373 | O16: =N16*(1+Inputs!O324) -> 84.557204 | ... T16: =S16*(1+Inputs!T324) -> 98.024975
B17: Legal & professional fees | C17: IDR bn | D17: Opex | G17: =Inputs!$E$325*Inputs!$F$325 -> 6.6470019 | H17: =G17*(1+Inputs!H325) -> 6.8464119 | I17: =H17*(1+Inputs!I325) -> 7.0518043 | J17: =I17*(1+Inputs!J325) -> 7.2633584 | K17: =J17*(1+Inputs!K325) -> 7.4812592 | L17: =K17*(1+Inputs!L325) -> 7.705697 | M17: =L17*(1+Inputs!M325) -> 7.9368679 | N17: =M17*(1+Inputs!N325) -> 8.1749739 | O17: =N17*(1+Inputs!O325) -> 8.4202231 | ... T17: =S17*(1+Inputs!T325) -> 9.7613464
B18: Staff costs - G&A (payroll) (growth = Inputs row + C13 x staff-row delta, Source Data 18) | C18: IDR bn | D18: Opex | G18: =Inputs!$E$326*Inputs!$F$326 -> 2.557285 | H18: =G18*(1+Inputs!H326+Inputs!$E$751*'Source Data'!H960) -> 2.6340036 | I18: =H18*(1+Inputs!I326+Inputs!$E$751*'Source Data'!I960) -> 2.7130237 | J18: =I18*(1+Inputs!J326+Inputs!$E$751*'Source Data'!J960) -> 2.7944144 | K18: =J18*(1+Inputs!K326+Inputs!$E$751*'Source Data'!K960) -> 2.8782468 | L18: =K18*(1+Inputs!L326+Inputs!$E$751*'Source Data'!L960) -> 2.9645942 | M18: =L18*(1+Inputs!M326+Inputs!$E$751*'Source Data'!M960) -> 3.0535321 | N18: =M18*(1+Inputs!N326+Inputs!$E$751*'Source Data'!N960) -> 3.145138 | O18: =N18*(1+Inputs!O326+Inputs!$E$751*'Source Data'!O960) -> 3.2394922 | ... T18: =S18*(1+Inputs!T326+Inputs!$E$751*'Source Data'!T960) -> 3.7554593
B19: Tax fees | C19: IDR bn | D19: Opex | G19: =Inputs!$E$327*Inputs!$F$327 -> 1.0491002 | H19: =G19*(1+Inputs!H327) -> 1.0805732 | I19: =H19*(1+Inputs!I327) -> 1.1129904 | J19: =I19*(1+Inputs!J327) -> 1.1463802 | K19: =J19*(1+Inputs!K327) -> 1.1807716 | L19: =K19*(1+Inputs!L327) -> 1.2161947 | M19: =L19*(1+Inputs!M327) -> 1.2526806 | N19: =M19*(1+Inputs!N327) -> 1.290261 | O19: =N19*(1+Inputs!O327) -> 1.3289688 | ... T19: =S19*(1+Inputs!T327) -> 1.5406391
B20: Travel & entertainment | C20: IDR bn | D20: Opex | G20: =Inputs!$E$328*Inputs!$F$328 -> 0.9944918 | H20: =G20*(1+Inputs!H328) -> 1.0243266 | I20: =H20*(1+Inputs!I328) -> 1.0550564 | J20: =I20*(1+Inputs!J328) -> 1.086708 | K20: =J20*(1+Inputs!K328) -> 1.1193093 | L20: =K20*(1+Inputs!L328) -> 1.1528886 | M20: =L20*(1+Inputs!M328) -> 1.1874752 | N20: =M20*(1+Inputs!N328) -> 1.2230995 | O20: =N20*(1+Inputs!O328) -> 1.2597925 | ... T20: =S20*(1+Inputs!T328) -> 1.4604447
B21: Office expenses | C21: IDR bn | D21: Opex | G21: =Inputs!$E$329*Inputs!$F$329 -> 0.78596338 | H21: =G21*(1+Inputs!H329) -> 0.80168264 | I21: =H21*(1+Inputs!I329) -> 0.8177163 | J21: =I21*(1+Inputs!J329) -> 0.83407062 | K21: =J21*(1+Inputs!K329) -> 0.85075204 | L21: =K21*(1+Inputs!L329) -> 0.86776708 | M21: =L21*(1+Inputs!M329) -> 0.88512242 | N21: =M21*(1+Inputs!N329) -> 0.90282487 | O21: =N21*(1+Inputs!O329) -> 0.92088136 | ... T21: =S21*(1+Inputs!T329) -> 1.0167274
B22: Other administrative | C22: IDR bn | D22: Opex | G22: =Inputs!$E$330*Inputs!$F$330 -> 0.65834446 | H22: =G22*(1+Inputs!H330) -> 0.6780948 | I22: =H22*(1+Inputs!I330) -> 0.69843764 | J22: =I22*(1+Inputs!J330) -> 0.71939077 | K22: =J22*(1+Inputs!K330) -> 0.74097249 | L22: =K22*(1+Inputs!L330) -> 0.76320167 | M22: =L22*(1+Inputs!M330) -> 0.78609772 | N22: =M22*(1+Inputs!N330) -> 0.80968065 | O22: =N22*(1+Inputs!O330) -> 0.83397107 | ... T22: =S22*(1+Inputs!T330) -> 0.96680104
B23: Rental - G&A | C23: IDR bn | D23: Opex | G23: =Inputs!$E$331*Inputs!$F$331 -> 0.27408379 | H23: =G23*(1+Inputs!H331) -> 0.27956546 | I23: =H23*(1+Inputs!I331) -> 0.28515677 | J23: =I23*(1+Inputs!J331) -> 0.29085991 | K23: =J23*(1+Inputs!K331) -> 0.29667711 | L23: =K23*(1+Inputs!L331) -> 0.30261065 | M23: =L23*(1+Inputs!M331) -> 0.30866286 | N23: =M23*(1+Inputs!N331) -> 0.31483612 | O23: =N23*(1+Inputs!O331) -> 0.32113284 | ... T23: =S23*(1+Inputs!T331) -> 0.35455661
B24: Depreciation - G&A | C24: IDR bn | D24: D&A | G24: =Inputs!$E$332*Inputs!$F$332 -> 0.2683397 | H24: =G24*(1+Inputs!H332) -> 0.27370649 | I24: =H24*(1+Inputs!I332) -> 0.27918062 | J24: =I24*(1+Inputs!J332) -> 0.28476424 | K24: =J24*(1+Inputs!K332) -> 0.29045952 | L24: =K24*(1+Inputs!L332) -> 0.29626871 | M24: =L24*(1+Inputs!M332) -> 0.30219409 | N24: =M24*(1+Inputs!N332) -> 0.30823797 | O24: =N24*(1+Inputs!O332) -> 0.31440273 | ... T24: =S24*(1+Inputs!T332) -> 0.34712601
B25: Communication | C25: IDR bn | D25: Opex | G25: =Inputs!$E$333*Inputs!$F$333 -> 0.22527943 | H25: =G25*(1+Inputs!H333) -> 0.22978501 | I25: =H25*(1+Inputs!I333) -> 0.23438071 | J25: =I25*(1+Inputs!J333) -> 0.23906833 | K25: =J25*(1+Inputs!K333) -> 0.2438497 | L25: =K25*(1+Inputs!L333) -> 0.24872669 | M25: =L25*(1+Inputs!M333) -> 0.25370122 | N25: =M25*(1+Inputs!N333) -> 0.25877525 | O25: =N25*(1+Inputs!O333) -> 0.26395075 | ... T25: =S25*(1+Inputs!T333) -> 0.29142296
B26: Security services | C26: IDR bn | D26: Opex | G26: =Inputs!$E$334*Inputs!$F$334 -> 0.21282385 | H26: =G26*(1+Inputs!H334) -> 0.21920857 | I26: =H26*(1+Inputs!I334) -> 0.22578483 | J26: =I26*(1+Inputs!J334) -> 0.23255837 | K26: =J26*(1+Inputs!K334) -> 0.23953512 | L26: =K26*(1+Inputs!L334) -> 0.24672118 | M26: =L26*(1+Inputs!M334) -> 0.25412281 | N26: =M26*(1+Inputs!N334) -> 0.2617465 | O26: =N26*(1+Inputs!O334) -> 0.26959889 | ... T26: =S26*(1+Inputs!T334) -> 0.31253901
B27: Donation & CSR | C27: IDR bn | D27: Opex | G27: =Inputs!$E$335*Inputs!$F$335 -> 0.1923315 | H27: =G27*(1+Inputs!H335) -> 0.19810144 | I27: =H27*(1+Inputs!I335) -> 0.20404449 | J27: =I27*(1+Inputs!J335) -> 0.21016582 | K27: =J27*(1+Inputs!K335) -> 0.2164708 | L27: =K27*(1+Inputs!L335) -> 0.22296492 | M27: =L27*(1+Inputs!M335) -> 0.22965387 | N27: =M27*(1+Inputs!N335) -> 0.23654348 | O27: =N27*(1+Inputs!O335) -> 0.24363979 | ... T27: =S27*(1+Inputs!T335) -> 0.28244529
B28: Utilities | C28: IDR bn | D28: Opex | G28: =Inputs!$E$336*Inputs!$F$336 -> 0.0021012075 | H28: =G28*(1+Inputs!H336) -> 0.0021432317 | I28: =H28*(1+Inputs!I336) -> 0.0021860963 | J28: =I28*(1+Inputs!J336) -> 0.0022298182 | K28: =J28*(1+Inputs!K336) -> 0.0022744146 | L28: =K28*(1+Inputs!L336) -> 0.0023199029 | M28: =L28*(1+Inputs!M336) -> 0.0023663009 | N28: =M28*(1+Inputs!N336) -> 0.0024136269 | O28: =N28*(1+Inputs!O336) -> 0.0024618995 | ... T28: =S28*(1+Inputs!T336) -> 0.002718136
B29: Memo: scheduled depreciation of existing assets (insurance base; Inputs 4) | C29: IDR bn | H29: =Inputs!H112 -> 41.467076 | I29: =Inputs!I112 -> 41.467076 | J29: =Inputs!J112 -> 42.467076 | K29: =Inputs!K112 -> 42.467076 | L29: =Inputs!L112 -> 42.467076 | M29: =Inputs!M112 -> 43.467076 | N29: =Inputs!N112 -> 43.467076 | O29: =Inputs!O112 -> 43.467076 | ... T29: =Inputs!T112 -> 44.467076
B30: Cost of sales - fixed lines (employees, security) x cost lever | C30: IDR bn | H30: =SUMIF($D$9:$D$28,"COGS fixed",H$9:H$28)*Inputs!$E$54 -> 15.484977 | I30: =SUMIF($D$9:$D$28,"COGS fixed",I$9:I$28)*Inputs!$E$54 -> 16.026951 | J30: =SUMIF($D$9:$D$28,"COGS fixed",J$9:J$28)*Inputs!$E$54 -> 16.587894 | K30: =SUMIF($D$9:$D$28,"COGS fixed",K$9:K$28)*Inputs!$E$54 -> 17.16847 | L30: =SUMIF($D$9:$D$28,"COGS fixed",L$9:L$28)*Inputs!$E$54 -> 17.769367 | M30: =SUMIF($D$9:$D$28,"COGS fixed",M$9:M$28)*Inputs!$E$54 -> 18.391295 | N30: =SUMIF($D$9:$D$28,"COGS fixed",N$9:N$28)*Inputs!$E$54 -> 19.03499 | O30: =SUMIF($D$9:$D$28,"COGS fixed",O$9:O$28)*Inputs!$E$54 -> 19.701215 | ... T30: =SUMIF($D$9:$D$28,"COGS fixed",T$9:T$28)*Inputs!$E$54 -> 23.398863
B31: Cost of sales - volume-driven (sum of unit costs x throughput / 1e9) x cost lever | C31: IDR bn | H31: =SUMIF($D$9:$D$28,"COGS per t",H$9:H$28)*'Revenue Calculation'!H38/1000000000*Inputs!$E$54 -> 13.565484 | I31: =SUMIF($D$9:$D$28,"COGS per t",I$9:I$28)*'Revenue Calculation'!I38/1000000000*Inputs!$E$54 -> 14.401947 | J31: =SUMIF($D$9:$D$28,"COGS per t",J$9:J$28)*'Revenue Calculation'!J38/1000000000*Inputs!$E$54 -> 15.290032 | K31: =SUMIF($D$9:$D$28,"COGS per t",K$9:K$28)*'Revenue Calculation'!K38/1000000000*Inputs!$E$54 -> 16.232929 | L31: =SUMIF($D$9:$D$28,"COGS per t",L$9:L$28)*'Revenue Calculation'!L38/1000000000*Inputs!$E$54 -> 17.234023 | M31: =SUMIF($D$9:$D$28,"COGS per t",M$9:M$28)*'Revenue Calculation'!M38/1000000000*Inputs!$E$54 -> 18.296909 | N31: =SUMIF($D$9:$D$28,"COGS per t",N$9:N$28)*'Revenue Calculation'!N38/1000000000*Inputs!$E$54 -> 19.425407 | O31: =SUMIF($D$9:$D$28,"COGS per t",O$9:O$28)*'Revenue Calculation'!O38/1000000000*Inputs!$E$54 -> 20.623568 | ... T31: =SUMIF($D$9:$D$28,"COGS per t",T$9:T$28)*'Revenue Calculation'!T38/1000000000*Inputs!$E$54 -> 27.819676
