Workbook

Sheet Navigation
B1: FSL — FKS Solusi Logistik — Financial Model (revised from v29)
B2: Valuation date 31-Dec-2026 · IDR bn unless stated · Sapphire excluded · two BUMN cases · built with live Excel formulas
B4: Start here
B5: Model Flow | C5: How the model is organised, what changed versus v29, how to use the controls, tests performed.
B6: Global Inputs | C6: Shared assumptions, switches (depreciation method, funding case, Badas funding), valuation parameters, project register (inclusion / case / interest).
B7: Project Summary | C7: One section per project (income statement, FCFF, capex, funding need, returns) + comparison table.
B8: FSL Financials — Without BUMN | C8: Integrated statements — Without BUMN case.
B9: FSL Financials — With BUMN | C9: Integrated statements — With BUMN case.
B10: Funding Requirement | C10: How much equity do we need and when: cash roll-forward, requirement at the injection date, capex-only projects, bridge, use of proceeds.
B11: Financing | C11: Corporate loans: LT loan carried until the capital injection; interest to the repayment date; injection booking.
B12: Valuation — Without BUMN | C12: DCF from FY2027 at 31-Dec-2026 — Without BUMN.
B13: Valuation — With BUMN | C13: DCF from FY2027 at 31-Dec-2026 — With BUMN.
B14: Checks | C14: Formula-based integrity checks (balance sheet, cash, consolidation, funding, valuation timing, capex allocation).
B15: Reconciliation v29 | C15: Line-by-line reconciliation to v29 (Output_FSL) with explanations of the differences.
B17: Project | C17: Description | D17: Input | E17: Calc | F17: Output | G17: Category / notes
B18: E1 Teluk Lamong (NPLOG) cargodoring & delivery | C18: Existing grain and meal terminal operations at Teluk Lamong (conveyor, warehouse, delivery): volume x tariff for meals and grains; variable costs per ton indexed from FY2023; fixed G&A lines; depreciation of existing assets. | D18: Input | E18: Calc | F18: Output | G18: Existing business — NPLOG Teluk Lamong
B19: E2 Cigading Existing Terminal (SGT 2) | C19: Existing grain terminal at Cigading: stevedoring / cargodoring volume at a per-ton tariff (Wharf 2 tariff from FY2025), variable costs per ton indexed from FY2023 actuals, fixed G&A lines, depreciation of existing assets. | D19: Input | E19: Calc | F19: Output | G19: Existing business — SGT Cigading
B20: E3 Belawan terminal (SGT3) incl. Belawan expansion | C20: Existing grain terminal at Belawan plus its expansion: existing volume (3% growth) and typed additional expansion volume from FY2027 at a per-ton tariff; fixed and per-ton costs indexed from FY2023, concession fee 2.5% of revenue, insurance; nine fixed G&A lines; existing-asset depreciation plus 14.0 USD m of new assets depreciated from FY2026. | D20: Input | E20: Calc | F20: Output | G20: Existing business — SGT Belawan
B21: E4 WIN stevedoring (Cilegon, Makassar, Surabaya, Medan) | C21: Existing stevedoring business at four ports: per-commodity volume (FY2023 base x growth index) x stevedoring tariff; cost of sales = dock & port facilities fee (share of sales), employee cost, maintenance and insurance; fixed G&A lines; fixed depreciation of existing assets per site. | D21: Input | E21: Calc | F21: Output | G21: Existing business — WIN
B22: P01 Cigading Wharf 2 | C22: Second wharf at Cigading: additional meals/grains volume at a stevedoring tariff; variable costs use the existing terminal's cost per ton, opex 20% of revenue, insurance on new assets. | D22: Input | E22: Calc | F22: Output | G22: Committed project — SGT Cigading
B23: P02 Cigading Extended Conveyor | C23: Conveyor extension at Cigading: additional cargodoring volume charged at a per-ton tariff; costs are electricity and maintenance shares of the existing terminal's cost per ton plus insurance on the new assets. | D23: Input | E23: Calc | F23: Output | G23: Committed project — SGT Cigading
B24: P03 KBS Warehouse Revitalisation (Cigading) | C24: Revitalisation of the KBS warehouse at Cigading: handling/bagging, weighing and storage fees per ton on an indexed 1.7 m t base; FKS books 49% of gross revenue, with cost of sales 10% and opex 50% of that revenue. | D24: Input | E24: Calc | F24: Output | G24: Planned project — SGT Cigading / KBS
B25: P04 Teluk Lamong Silo | C25: Two 8,500 t/month silos at Teluk Lamong charging a bagging/storage fee of 65,000 IDR per ton per month from 2027; a 300 IDR/t handling cost (booked as opex in v29) and depreciation of the 3.76 USD m capex (building 63% / 20 yrs, equipment 37% / 10 yrs). | D25: Input | E25: Calc | F25: Output | G25: Planned project — NPLOG Teluk Lamong
B26: P05 Dumai bagging & weighbridge | C26: Bagging and weighbridge services at Dumai from FY2026: a typed volume schedule (1.3 m t, stepping up 3% every four years) charged a bagging tariff (35,000 IDR/t, +4% every four years) and a weighbridge tariff (2,000 IDR/t); opex = insurance on the 6.81 USD m capex plus operational cost as a typed % of each revenue stream; cost of sales nil in v29. | D26: Input | E26: Calc | F26: Output | G26: Planned project — FSL Dumai
B27: P06 Ciwandan Expansion | C27: Expansion at Ciwandan from FY2028: 1.6 m t growing 10% p.a. (6% from 2032) at an ASP of 36,411 IDR/t stepping up with the Cigading tariff; cost of sales and opex are the existing Cigading terminal's cost-to-revenue ratios applied to the expansion revenue; depreciation of the 5.02 USD m capex (50% building / 20 yrs, 50% equipment / 8 yrs). | D27: Input | E27: Calc | F27: Output | G27: Planned project — FSL Ciwandan
B28: P08 DMS trucking fee (Teluk Lamong, Cigading, Ciwandan, Belawan) | C28: Digital trucking management service at four terminals: FKS earns a 2% service fee on the trucking cost per ton of each terminal's volume and keeps 50% of the fee; opex 20% of FKS revenue; small equipment depreciated per site (no capex in v29). | D28: Input | E28: Calc | F28: Output | G28: Planned project — DMS trucking
... B31: P19 Badas bulk terminal (FS pending — DUMMY data) | C31: Bulk cargo terminal at Badas: capacity x utilisation -> throughput; handling, storage and ancillary tariffs; variable, staff, fixed, maintenance, insurance and concession costs; 10 USD m provisional capex; project debt option. ALL operating inputs are DUMMY placeholders until the feasibility study is received. | D31: Input | E31: Calc | F31: Output | G31: Pipeline — FS pending (DUMMY inputs, excluded from headline valuation) — Badas (new)
B33: Colour conventions
C34: Blue text on pale yellow = hard-coded input (v29 source or derived)
C35: Bold blue on gold = control / switch
C36: Light blue = user-requested modelling change
C37: Light green = updated information supplied by the user
C38: Orange = provisional — to confirm
C39: Salmon = DUMMY — REPLACE WITH FS DATA (Badas)
C40: Black text = formula; green text = link from another sheet; blue underlined = navigation link

Sheet Model Flow
B1: MODEL FLOW — architecture, changes versus v29, controls, tests
B2: Detailed explanations live here so that calculation sheets stay focused on drivers and numbers.
B4: 1. Purpose | C4: Revised FSL model built from V29_Ruby_FM_Danantara.xlsm (v29) with live formulas. v29 remains the source of business assumptions and calculation logic; the changes requested by the user are: valuation date 31-Dec-2026 with a DCF from FY2027, LT loan repaid when the capital injection is received, capex spending controlled by annual percentages, Badas built as a feasibility-study working paper, a funding requirement sheet with five capex-only placeholders, and separate With / Without BUMN cases. Sapphire stays excluded.
B5: 2. Architecture | C5: Global Inputs (shared assumptions and the project register) -> one Input / Calc / Output triplet per project -> Project Summary and the two FSL Financials sheets (sum of project outputs x case flags + corporate items) -> Funding Requirement and Financing (LT loan, injection) -> two Valuation sheets -> Checks and Reconciliation. Sheet names carry the project ID and code (e.g. 'P02 CigConveyor Input / Calc / Output'). Every time-series sheet uses the same columns: F = 2023 (opening / pre-2024), G..S = 2024..2036.
B6: 3. Inputs and classification | C6: Column D on every input row classifies the assumption: v29 (value and cell reference from v29, including effective values typed inside v29 formulas), DERIVED (computed from v29), UPDATED (information supplied by the user, e.g. the board-deck use of proceeds), CHANGE (user-requested modelling change), DUMMY (Badas placeholders to be replaced with FS data), PROV (provisional, to confirm), CONTROL (switch). Annual assumptions have one editable cell per year; genuine one-off parameters sit in column E.
B7: 4. Project sheets | C7: Input: register, controls (links to Global Inputs), commissioning year, operating assumptions, capex allocation (total USD m, % by year, USD and IDR schedules, pre- vs post-valuation split, allocation check, building share, useful lives). Calc: operating flag, revenue and cost drivers exactly as v29 computes them, capex and depreciation, working capital. Output: unlevered project income statement (tax on project EBIT, v29 line method), FCFF, net operating assets (no project-level cash or debt), funding need, returns (NPV at the valuation date, full-life IRR with and without terminal value, payback), case inclusion flags.
B8: 5. Two BUMN cases | C8: v29 Output_FSL is the With-BUMN case: it includes the 'Operatorship with BUMN' block (FSL's entitlement under the Pelindo Teluk Lamong, KBS Cigading and Pelindo Belawan operatorship schemes; v29 Output_FSL!F35 = 1). The Without-BUMN case removes the case-2 projects (register column 'Case' = 2). Both cases are computed at the same time on their own Financials and Valuation sheets; the Funding Requirement uses the case selected on Global Inputs (default: Without BUMN, conservative). DMS trucking fees are shared 50/50 with the port operator but are kept in both cases as in v8; set their case to 2 on the register to treat them as BUMN-dependent.
B9: 6. Valuation date and DCF | C9: Valuation date 31-Dec-2026 (Global Inputs). Only FCFF of years after the valuation date enters the DCF (flag row 'DCF window'); FY2027 is discounted one full year (year-end convention). FCFF = EBIT - tax on EBIT (sum of project line taxes) + D&A - capex - increase in working capital, unlevered and consistent with WACC. Terminal value: Gordon growth on a normalised FY2036 cash flow (capex = factor x depreciation, working capital growing with g). Equity bridge at 31-Dec-2026: + cash, - LT loan outstanding at that date (depends on whether the injection date falls before or after it), +/- other balances (switch), - non-controlling interests (35% of NPLOG line values).
B10: 7. LT loan and capital injection | C10: The 12 USD m LT loan (195.2 IDR bn) is carried until the capital injection. Injection date and mode are inputs on Global Inputs (provisional 30-Jun-2027). Mode 1 sizes the injection to the equity requirement of the funding case; mode 2 uses a fixed amount. Repayment = planned share of the balance in the injection year, limited in mode 2 to the proceeds received; any unpaid balance is retained, flagged, and keeps accruing interest. Interest accrues on the repaid part to the injection date and on the remaining balance for the full year. The equity receipt and the loan repayment are separate lines in the cash-flow statement. No circular references: the requirement is computed on a pre-equity cash path; dividends are capped by that path so they are never paid out of the injection.
B11: 8. Capex percentages | C11: Each project's capex = total (USD m) x annual % of total (Input sheet). The 2023 column is pre-2024 (sunk) spend; columns up to the valuation year are pre-valuation estimates (v29 projected timing; actuals not supplied — flag 'historical spend confirmed' = 0). Only spend after the valuation date enters the 2027+ DCF. Depreciation method switch: 2 (default) depreciates each year's spend over its life from MAX(spend year, commissioning); 1 reproduces v29 (total x share / life from commissioning, no end).
B12: 9. Badas | C12: P19 Badas is a complete project template with DUMMY inputs (salmon rows, 'DUMMY — REPLACE WITH FS DATA'). Its working paper lists definition, unit, period, status and destination for every requested input plus questions for the operations team. Badas is excluded from the headline valuation by default (register 'In valuation' = 0) while its capex (provisional 10 USD m from the board deck) enters the funding request through the separate 'Badas in funding' switch.
B13: 10. Funding-only placeholders | C13: F01-F05 on the Funding Requirement sheet accept a name, total capex (USD m), annual % and an include switch. They add to the equity request only; they never enter the statements or the valuation and carry no revenue, profit or return ('FS not available').
B14: 11. Corporate and unallocated items | C14: Existing fixed assets (Dec-23 NBV 826.0), other assets, other liabilities, inventory, the loans and paid-in capital are company-level balances from v29 and are not allocated to projects. Dec-23 receivables and payables are allocated to the existing businesses pro rata FY2024 activity (labelled as an allocation). Pre-2024 project spend on Wharf 2 and the conveyor (assets under construction) is reclassified from other assets to project fixed assets.
B15: 12. Reconciliation to v29 | C15: The Reconciliation sheet compares the With-BUMN case with v29 Output_FSL line by line and explains each difference (valuation date, LT loan timing and interest, depreciation method, injection basis, inventory and other v29 formula breaks). Setting depreciation method = 1 and the injection date to 31-Dec-2025 reproduces v29's income statement through EBIT; v29's two equity tranches (FY2026-27 capex) are replaced by one requirement-based injection.
... B17: 14. Calculation engine and tests | C17: Recalculated and tested with LibreOffice Calc (headless), not Microsoft Excel. Tests: injection date moved (2026 / 2028) moves the repayment and interest; zero / insufficient proceeds keep the loan outstanding; capex % moved between years updates capex, depreciation, cash and funding; Badas dummy inputs replaced update its sheets; inclusion switches affect the correct case; funding-only placeholders change the request but not the valuation; project outputs reconcile to company outputs; balance sheets and cash reconcile. Settings were restored to the delivery values after testing (see model/tests/).

Sheet Global Inputs
B1: GLOBAL INPUTS — shared assumptions, controls and project register
B2: Single source for every assumption used by more than one sheet. Blue = input (yellow fill); bold blue on gold = control switch; orange = provisional; light blue = user-requested change. Black = formula.
B3: Go to: | C3: Navigation | D3: Global Inputs | E3: Project Summary | F3: Funding | G3: FSL w/o BUMN | H3: FSL w/ BUMN | I3: Val w/o BUMN | J3: Val w/ BUMN | K3: Checks | L3: Model Flow
B5: Year | C5: Unit | D5: Type | E5: Value / total | F5: 2023 | G5: 2024 | H5: 2025 | I5: 2026 | J5: 2027 | K5: 2028 | L5: 2029 | M5: 2030 | N5: 2031 | O5: 2032 | P5: 2033 | Q5: 2034 | R5: 2035 | S5: 2036 | T5: Source (v29 reference / basis) | U5: Note
B6: Period end | F6: =DATE(F5,12,31) -> 45291 | G6: =DATE(G5,12,31) -> 45657 | H6: =DATE(H5,12,31) -> 46022 | I6: =DATE(I5,12,31) -> 46387 | J6: =DATE(J5,12,31) -> 46752 | K6: =DATE(K5,12,31) -> 47118 | L6: =DATE(L5,12,31) -> 47483 | M6: =DATE(M5,12,31) -> 47848 | ... S6: =DATE(S5,12,31) -> 50040
B7: Days in year | F7: =F6-DATE(F5,1,1)+1 -> 365 | G7: =G6-DATE(G5,1,1)+1 -> 366 | H7: =H6-DATE(H5,1,1)+1 -> 365 | I7: =I6-DATE(I5,1,1)+1 -> 365 | J7: =J6-DATE(J5,1,1)+1 -> 365 | K7: =K6-DATE(K5,1,1)+1 -> 366 | L7: =L6-DATE(L5,1,1)+1 -> 365 | M7: =M6-DATE(M5,1,1)+1 -> 365 | ... S7: =S6-DATE(S5,1,1)+1 -> 366
B8: Forecast flag (1 = forecast year) | F8: 0 | G8: 1 | H8: 1 | I8: 1 | J8: 1 | K8: 1 | L8: 1 | M8: 1 | N8: 1 | O8: 1 | P8: 1 | Q8: 1 | R8: 1 | S8: 1
B10: 1. Timeline and valuation date
B11: Valuation date | C11: date | D11: CHANGE | E11: 46387 | T11: User instruction (change from v29 which valued at model start) | U11: Company DCF uses FCFF from the year after this date (FY2027+). Balances at this date enter the equity bridge.
B12: Valuation year (financial year ending on the valuation date) | C12: year | D12: formula | E12: =YEAR($E$11) -> 2026 | T12: Formula
B13: First year of DCF cash flows | C13: year | D13: formula | E13: =$E$12+1 -> 2027 | T13: Formula
B14: Last explicit forecast year | C14: year | D14: formula | E14: =MAX(F5:S5) -> 2036 | T14: Formula
B15: Model year (header) | C15: year | D15: formula | F15: =F$5 -> 2023 | G15: =G$5 -> 2024 | H15: =H$5 -> 2025 | I15: =I$5 -> 2026 | J15: =J$5 -> 2027 | K15: =K$5 -> 2028 | L15: =L$5 -> 2029 | M15: =M$5 -> 2030 | ... S15: =S$5 -> 2036 | T15: Timeline
B16: DCF window flag (1 = year after the valuation date) | C16: flag | D16: formula | F16: =IF(F$5>$E$12,1,0) -> 0 | G16: =IF(G$5>$E$12,1,0) -> 0 | H16: =IF(H$5>$E$12,1,0) -> 0 | I16: =IF(I$5>$E$12,1,0) -> 0 | J16: =IF(J$5>$E$12,1,0) -> 1 | K16: =IF(K$5>$E$12,1,0) -> 1 | L16: =IF(L$5>$E$12,1,0) -> 1 | M16: =IF(M$5>$E$12,1,0) -> 1 | ... S16: =IF(S$5>$E$12,1,0) -> 1 | T16: Formula
B17: Discount period (years from the valuation date; year-end convention) | C17: years | D17: formula | F17: =IF(F$5>$E$12,F$5-$E$12,0) -> 0 | G17: =IF(G$5>$E$12,G$5-$E$12,0) -> 0 | H17: =IF(H$5>$E$12,H$5-$E$12,0) -> 0 | I17: =IF(I$5>$E$12,I$5-$E$12,0) -> 0 | J17: =IF(J$5>$E$12,J$5-$E$12,0) -> 1 | K17: =IF(K$5>$E$12,K$5-$E$12,0) -> 2 | L17: =IF(L$5>$E$12,L$5-$E$12,0) -> 3 | M17: =IF(M$5>$E$12,M$5-$E$12,0) -> 4 | ... S17: =IF(S$5>$E$12,S$5-$E$12,0) -> 10 | T17: Formula | U17: FY2027 cash flow is discounted one full year from 31-Dec-2026.
B18: Discount factor at WACC (0 before / at the valuation date) | C18: x | D18: formula | F18: =IF(F$5>$E$12,1/(1+$E$53)^F17,0) -> 0 | G18: =IF(G$5>$E$12,1/(1+$E$53)^G17,0) -> 0 | H18: =IF(H$5>$E$12,1/(1+$E$53)^H17,0) -> 0 | I18: =IF(I$5>$E$12,1/(1+$E$53)^I17,0) -> 0 | J18: =IF(J$5>$E$12,1/(1+$E$53)^J17,0) -> 0.89392257 | K18: =IF(K$5>$E$12,1/(1+$E$53)^K17,0) -> 0.79909756 | L18: =IF(L$5>$E$12,1/(1+$E$53)^L17,0) -> 0.71433135 | M18: =IF(M$5>$E$12,1/(1+$E$53)^M17,0) -> 0.63855691 | ... S18: =IF(S$5>$E$12,1/(1+$E$53)^S17,0) -> 0.32583597 | T18: Formula
B19: Pre-valuation flag (1 = up to and including the valuation year) | C19: flag | D19: formula | F19: =IF(F$5<=$E$12,1,0) -> 1 | G19: =IF(G$5<=$E$12,1,0) -> 1 | H19: =IF(H$5<=$E$12,1,0) -> 1 | I19: =IF(I$5<=$E$12,1,0) -> 1 | J19: =IF(J$5<=$E$12,1,0) -> 0 | K19: =IF(K$5<=$E$12,1,0) -> 0 | L19: =IF(L$5<=$E$12,1,0) -> 0 | M19: =IF(M$5<=$E$12,1,0) -> 0 | ... S19: =IF(S$5<=$E$12,1,0) -> 0 | T19: Formula
B21: 2. Exchange rate
B22: Exchange rate USD/IDR (applied to capex, USD presentation) | C22: IDR/USD | D22: v29 | F22: 16265 | G22: 16265 | H22: 16265 | I22: 16265 | J22: 16265 | K22: 16265 | L22: 16265 | M22: 16265 | N22: 16265 | O22: 16265 | P22: 16265 | Q22: 16265 | R22: 16265 | S22: 16265 | T22: Calculation_FSL!F17 (USD_IDR = 16,265, single rate in v29) | U22: v29 uses one rate for all years; each year is independently editable here.
B23: Exchange rate of the valuation year (USD presentation of values) | C23: IDR/USD | D23: formula | E23: =INDEX($F$22:$S$22,MATCH($E$12,$F$15:$S$15,0)) -> 16265 | T23: Formula
B24: Exchange rate of the opening column (FY2023) — used for Dec-23 USD balances | C24: IDR/USD | D24: formula | E24: =INDEX($F$22:$S$22,1) -> 16265 | T24: Formula
B26: 3. Tax and working capital
B27: Corporate income tax rate | C27: % | D27: v29 | E27: 0.22 | T27: Output_Standalone (IDR)!J33 etc. (22% typed in each v29 tax formula) | U27: Applied per project line to MAX(0, EBIT) — v29 method, no loss relief between lines.
B28: Receivable days (on revenue) | C28: days | D28: v29 | E28: 45 | T28: Calculation_FSL!F1454 | U28: Applied to every project line (v29 applies it to company revenue; result identical).
B29: Payable days (on cost of sales) | C29: days | D29: v29 | E29: 30 | T29: Calculation_FSL!F1464
B30: Inventory balance (held at the Dec-23 level; centrally held, not allocated to projects) | C30: IDR bn | D30: v29 | E30: 0.519811 | T30: Output_FSL!I96 (BS_Historical!V10/1000) | U30: v29 holds this balance to FY2033 and drops it to nil from FY2034 through a formula break (Calculation_FSL!T1460:V1460); held flat here — see Reconciliation.
B32: 4. Model switches
B33: Depreciation method for project capex: 1 = v29 (total capex x share / life from commissioning, no end), 2 = by year of spend over the useful life from MAX(spend year, commissioning) | C33: 1/2 | D33: CONTROL | E33: 2 | T33: User request (capex % allocation linked to depreciation); v29 method retained as option 1 | U33: Method 2 links depreciation to the capex allocation and stops at the end of the useful life. Set 1 to reproduce v29 depreciation.
B34: Corporate LT-loan interest tax shield at company level: 1 = deductible at the tax rate, 0 = no shield | C34: 0/1 | D34: CONTROL | E34: 1 | T34: Modelling judgement (v29 charged the interest to the Cigading existing / Wharf 2 lines and taxed each line separately)
B35: Dividend policy: 1 = v29 rules (30% of attributable profit, limited by reserve and cash before new equity), 0 = no dividends | C35: 0/1 | D35: CONTROL | E35: 1 | T35: Calculation_FSL rows 1527-1557
B36: Operating case underlying the Funding Requirement roll-forward: 1 = Without BUMN (conservative), 2 = With BUMN | C36: 1/2 | D36: CONTROL | E36: 1 | T36: User instruction: show which BUMN case underlies the funding calculation
B37: Include Badas capex in the funding request while Badas is outside the valuation (1 = yes) | C37: 0/1 | D37: CONTROL | E37: 1 | T37: User instruction (separate funding-inclusion control) | U37: When Badas is inside the valuation its capex is already in the company statements and this control is ignored.
B38: Include Dec-23 other assets / other liabilities (held flat) in the equity bridge: 1 = yes, 0 = no | C38: 0/1 | D38: PROV | E38: 0 | T38: Modelling judgement — classification of these balances (deposits, deferred tax, accruals) not available
B40: 5. Valuation parameters (discount rate build-up, terminal value) — PROVISIONAL, not in v29
B41: IDR 10-year government bond yield | C41: % | D41: PROV | E41: 0.0701 | T41: Not in v29 — provisional market parameter
B42: Indonesia sovereign default spread (removed from the bond yield) | C42: % | D42: PROV | E42: 0.0162 | T42: Not in v29 — provisional
B43: Equity risk premium incl. country risk | C43: % | D43: PROV | E43: 0.0669 | T43: Not in v29 — provisional
B44: Unlevered beta (port / logistics infrastructure) | C44: x | D44: PROV | E44: 0.8 | T44: Not in v29 — provisional
B45: Target debt / (debt + equity) | C45: % | D45: PROV | E45: 0.2 | T45: Not in v29 — provisional
B46: Pre-tax cost of debt | C46: % | D46: PROV | E46: 0.105 | T46: Call Rights!H71 note '10%-11%' (IDR) — provisional
...

Sheet Project Summary
B1: PROJECT SUMMARY — project-by-project results (concept of v29 Output_Standalone)
B2: Each section links to the project's Output sheet; the comparison table gives the headline numbers side by side. IDR bn unless stated.
B3: Go to: | C3: Navigation | D3: Global Inputs | E3: Project Summary | F3: Funding | G3: FSL w/o BUMN | H3: FSL w/ BUMN | I3: Val w/o BUMN | J3: Val w/ BUMN | K3: Checks | L3: Model Flow
B5: Year | C5: Unit | D5: Type | E5: Value / total | F5: ='Global Inputs'!F$5 -> 2023 | G5: ='Global Inputs'!G$5 -> 2024 | H5: ='Global Inputs'!H$5 -> 2025 | I5: ='Global Inputs'!I$5 -> 2026 | J5: ='Global Inputs'!J$5 -> 2027 | K5: ='Global Inputs'!K$5 -> 2028 | L5: ='Global Inputs'!L$5 -> 2029 | M5: ='Global Inputs'!M$5 -> 2030 | ... S5: ='Global Inputs'!S$5 -> 2036 | T5: Source (v29 reference / basis) | U5: Note
B6: Period end | F6: ='Global Inputs'!F$6 -> 45291 | G6: ='Global Inputs'!G$6 -> 45657 | H6: ='Global Inputs'!H$6 -> 46022 | I6: ='Global Inputs'!I$6 -> 46387 | J6: ='Global Inputs'!J$6 -> 46752 | K6: ='Global Inputs'!K$6 -> 47118 | L6: ='Global Inputs'!L$6 -> 47483 | M6: ='Global Inputs'!M$6 -> 47848 | ... S6: ='Global Inputs'!S$6 -> 50040
B7: Days in year | F7: ='Global Inputs'!F$7 -> 365 | G7: ='Global Inputs'!G$7 -> 366 | H7: ='Global Inputs'!H$7 -> 365 | I7: ='Global Inputs'!I$7 -> 365 | J7: ='Global Inputs'!J$7 -> 365 | K7: ='Global Inputs'!K$7 -> 366 | L7: ='Global Inputs'!L$7 -> 365 | M7: ='Global Inputs'!M$7 -> 365 | ... S7: ='Global Inputs'!S$7 -> 366
B8: Forecast flag (1 = forecast year) | F8: ='Global Inputs'!F$8 -> 0 | G8: ='Global Inputs'!G$8 -> 1 | H8: ='Global Inputs'!H$8 -> 1 | I8: ='Global Inputs'!I$8 -> 1 | J8: ='Global Inputs'!J$8 -> 1 | K8: ='Global Inputs'!K$8 -> 1 | L8: ='Global Inputs'!L$8 -> 1 | M8: ='Global Inputs'!M$8 -> 1 | ... S8: ='Global Inputs'!S$8 -> 1
B10: A. Comparison table — all projects (links to the project Output sheets; values in IDR bn unless stated)
B11: Project | C11: Category | D11: In val. | E11: Case | F11: FSL int. | G11: Start yr | H11: Capex USD m | I11: Capex post-val USD m | J11: Revenue 2027 | K11: Revenue 2030 | L11: EBITDA 2030 | M11: NPV @ 31-Dec-26 | N11: IRR full life | O11: Payback yr | P11: Input | Q11: Calc | R11: Output
B12: E1 Teluk Lamong (NPLOG) cargodoring & delivery | C12: Existing business | D12: ='Global Inputs'!$E$89 -> 1 | E12: ='Global Inputs'!$F$89 -> 1 | F12: ='Global Inputs'!$G$89 -> 0.65 | G12: ="existing" -> existing | H12: =0 -> 0 | I12: =0 -> 0 | J12: ='E1 TelukLamong Output'!$J$11 -> 170.94433 | K12: ='E1 TelukLamong Output'!$M$11 -> 192.39935 | L12: ='E1 TelukLamong Output'!$M$15 -> 136.39274 | M12: ='E1 TelukLamong Output'!$E$48 -> 1190.2163 | N12: =IF(ISNUMBER('E1 TelukLamong Output'!$E$50),'E1 TelukLamong Output'!$E$50,"n/a") -> n/a | O12: =IF(ISNUMBER('E1 TelukLamong Output'!$E$53),'E1 TelukLamong Output'!$E$53,"n/a") -> n/a | P12: open | Q12: open | R12: open
B13: E2 Cigading Existing Terminal (SGT 2) | C13: Existing business | D13: ='Global Inputs'!$E$90 -> 1 | E13: ='Global Inputs'!$F$90 -> 1 | F13: ='Global Inputs'!$G$90 -> 1 | G13: ="existing" -> existing | H13: =0 -> 0 | I13: =0 -> 0 | J13: ='E2 CigadingExist Output'!$J$11 -> 59.057611 | K13: ='E2 CigadingExist Output'!$M$11 -> 70.987231 | L13: ='E2 CigadingExist Output'!$M$15 -> 42.844418 | M13: ='E2 CigadingExist Output'!$E$48 -> 461.15059 | N13: =IF(ISNUMBER('E2 CigadingExist Output'!$E$50),'E2 CigadingExist Output'!$E$50,"n/a") -> n/a | O13: =IF(ISNUMBER('E2 CigadingExist Output'!$E$53),'E2 CigadingExist Output'!$E$53,"n/a") -> n/a | P13: open | Q13: open | R13: open
B14: E3 Belawan terminal (SGT3) incl. Belawan expansion | C14: Existing business | D14: ='Global Inputs'!$E$91 -> 1 | E14: ='Global Inputs'!$F$91 -> 1 | F14: ='Global Inputs'!$G$91 -> 1 | G14: ="existing" -> existing | H14: ='E3 Belawan Input'!$E$76 -> 14.024593 | I14: ='E3 Belawan Input'!$E$82 -> 7 | J14: ='E3 Belawan Output'!$J$11 -> 44.806465 | K14: ='E3 Belawan Output'!$M$11 -> 59.814057 | L14: ='E3 Belawan Output'!$M$15 -> 43.579698 | M14: ='E3 Belawan Output'!$E$48 -> 237.96397 | N14: =IF(ISNUMBER('E3 Belawan Output'!$E$50),'E3 Belawan Output'!$E$50,"n/a") -> n/a | O14: =IF(ISNUMBER('E3 Belawan Output'!$E$53),'E3 Belawan Output'!$E$53,"n/a") -> 2032 | P14: open | Q14: open | R14: open
B15: E4 WIN stevedoring (Cilegon, Makassar, Surabaya, Medan) | C15: Existing business | D15: ='Global Inputs'!$E$92 -> 1 | E15: ='Global Inputs'!$F$92 -> 1 | F15: ='Global Inputs'!$G$92 -> 1 | G15: ="existing" -> existing | H15: =0 -> 0 | I15: =0 -> 0 | J15: ='E4 WIN Output'!$J$11 -> 66.857705 | K15: ='E4 WIN Output'!$M$11 -> 83.887124 | L15: ='E4 WIN Output'!$M$15 -> 24.471909 | M15: ='E4 WIN Output'!$E$48 -> 213.66342 | N15: =IF(ISNUMBER('E4 WIN Output'!$E$50),'E4 WIN Output'!$E$50,"n/a") -> n/a | O15: =IF(ISNUMBER('E4 WIN Output'!$E$53),'E4 WIN Output'!$E$53,"n/a") -> n/a | P15: open | Q15: open | R15: open
B16: P01 Cigading Wharf 2 | C16: Committed project | D16: ='Global Inputs'!$E$93 -> 1 | E16: ='Global Inputs'!$F$93 -> 1 | F16: ='Global Inputs'!$G$93 -> 1 | G16: ='P01 CigWharf2 Input'!$E$25 -> 2025 | H16: ='P01 CigWharf2 Input'!$E$36 -> 12.8 | I16: ='P01 CigWharf2 Input'!$E$42 -> 0 | J16: ='P01 CigWharf2 Output'!$J$11 -> 127.70547 | K16: ='P01 CigWharf2 Output'!$M$11 -> 153.50193 | L16: ='P01 CigWharf2 Output'!$M$15 -> 110.37226 | M16: ='P01 CigWharf2 Output'!$E$47 -> 960.01466 | N16: =IF(ISNUMBER('P01 CigWharf2 Output'!$E$49),'P01 CigWharf2 Output'!$E$49,"n/a") -> 0.27587356 | O16: =IF(ISNUMBER('P01 CigWharf2 Output'!$E$52),'P01 CigWharf2 Output'!$E$52,"n/a") -> 2028 | P16: open | Q16: open | R16: open
B17: P02 Cigading Extended Conveyor | C17: Committed project | D17: ='Global Inputs'!$E$94 -> 1 | E17: ='Global Inputs'!$F$94 -> 1 | F17: ='Global Inputs'!$G$94 -> 1 | G17: ='P02 CigConveyor Input'!$E$25 -> 2025 | H17: ='P02 CigConveyor Input'!$E$36 -> 8 | I17: ='P02 CigConveyor Input'!$E$42 -> 0 | J17: ='P02 CigConveyor Output'!$J$11 -> 33.41835 | K17: ='P02 CigConveyor Output'!$M$11 -> 36.517133 | L17: ='P02 CigConveyor Output'!$M$15 -> 33.479033 | M17: ='P02 CigConveyor Output'!$E$47 -> 280.51826 | N17: =IF(ISNUMBER('P02 CigConveyor Output'!$E$49),'P02 CigConveyor Output'!$E$49,"n/a") -> 0.16210365 | O17: =IF(ISNUMBER('P02 CigConveyor Output'!$E$52),'P02 CigConveyor Output'!$E$52,"n/a") -> 2030 | P17: open | Q17: open | R17: open
B18: P03 KBS Warehouse Revitalisation (Cigading) | C18: Planned project | D18: ='Global Inputs'!$E$95 -> 1 | E18: ='Global Inputs'!$F$95 -> 1 | F18: ='Global Inputs'!$G$95 -> 1 | G18: ='P03 KBSWarehouse Input'!$E$25 -> 2027 | H18: ='P03 KBSWarehouse Input'!$E$40 -> 6.02459 | I18: ='P03 KBSWarehouse Input'!$E$46 -> 0 | J18: ='P03 KBSWarehouse Output'!$J$11 -> 53.023782 | K18: ='P03 KBSWarehouse Output'!$M$11 -> 57.940518 | L18: ='P03 KBSWarehouse Output'!$M$15 -> 23.176207 | M18: ='P03 KBSWarehouse Output'!$E$47 -> 189.57925 | N18: =IF(ISNUMBER('P03 KBSWarehouse Output'!$E$49),'P03 KBSWarehouse Output'!$E$49,"n/a") -> 0.13347383 | O18: =IF(ISNUMBER('P03 KBSWarehouse Output'!$E$52),'P03 KBSWarehouse Output'!$E$52,"n/a") -> 2032 | P18: open | Q18: open | R18: open
B19: P04 Teluk Lamong Silo | C19: Planned project | D19: ='Global Inputs'!$E$96 -> 1 | E19: ='Global Inputs'!$F$96 -> 1 | F19: ='Global Inputs'!$G$96 -> 1 | G19: ='P04 TTLSilo Input'!$E$25 -> 2027 | H19: ='P04 TTLSilo Input'!$E$39 -> 3.7623 | I19: ='P04 TTLSilo Input'!$E$45 -> 0 | J19: ='P04 TTLSilo Output'!$J$11 -> 13.26 | K19: ='P04 TTLSilo Output'!$M$11 -> 13.26 | L19: ='P04 TTLSilo Output'!$M$15 -> 13.1988 | M19: ='P04 TTLSilo Output'!$E$47 -> 104.74445 | N19: =IF(ISNUMBER('P04 TTLSilo Output'!$E$49),'P04 TTLSilo Output'!$E$49,"n/a") -> 0.12284866 | O19: =IF(ISNUMBER('P04 TTLSilo Output'!$E$52),'P04 TTLSilo Output'!$E$52,"n/a") -> 2032 | P19: open | Q19: open | R19: open
B20: P05 Dumai bagging & weighbridge | C20: Planned project | D20: ='Global Inputs'!$E$97 -> 1 | E20: ='Global Inputs'!$F$97 -> 1 | F20: ='Global Inputs'!$G$97 -> 1 | G20: ='P05 Dumai Input'!$E$25 -> 2026 | H20: ='P05 Dumai Input'!$E$39 -> 6.8095238 | I20: ='P05 Dumai Input'!$E$45 -> 0.325 | J20: ='P05 Dumai Output'!$J$11 -> 48.1 | K20: ='P05 Dumai Output'!$M$11 -> 51.4176 | L20: ='P05 Dumai Output'!$M$15 -> 26.051324 | M20: ='P05 Dumai Output'!$E$47 -> 197.60397 | N20: =IF(ISNUMBER('P05 Dumai Output'!$E$49),'P05 Dumai Output'!$E$49,"n/a") -> 0.1925954 | O20: =IF(ISNUMBER('P05 Dumai Output'!$E$52),'P05 Dumai Output'!$E$52,"n/a") -> 2031 | P20: open | Q20: open | R20: open
B21: P06 Ciwandan Expansion | C21: Planned project | D21: ='Global Inputs'!$E$98 -> 1 | E21: ='Global Inputs'!$F$98 -> 1 | F21: ='Global Inputs'!$G$98 -> 1 | G21: ='P06 Ciwandan Input'!$E$25 -> 2028 | H21: ='P06 Ciwandan Input'!$E$33 -> 5.0245927 | I21: ='P06 Ciwandan Input'!$E$39 -> 2.5122963 | J21: ='P06 Ciwandan Output'!$J$11 -> 0 | K21: ='P06 Ciwandan Output'!$M$11 -> 84.590383 | L21: ='P06 Ciwandan Output'!$M$15 -> 50.88063 | M21: ='P06 Ciwandan Output'!$E$47 -> 475.82384 | N21: =IF(ISNUMBER('P06 Ciwandan Output'!$E$49),'P06 Ciwandan Output'!$E$49,"n/a") -> 0.38580025 | O21: =IF(ISNUMBER('P06 Ciwandan Output'!$E$52),'P06 Ciwandan Output'!$E$52,"n/a") -> 2030 | P21: open | Q21: open | R21: open
B22: P08 DMS trucking fee (Teluk Lamong, Cigading, Ciwandan, Belawan) | C22: Planned project | D22: ='Global Inputs'!$E$99 -> 1 | E22: ='Global Inputs'!$F$99 -> 1 | F22: ='Global Inputs'!$G$99 -> 1 | G22: ='P08 DMSTrucking Input'!$E$25 -> 2027 | H22: =0 -> 0 | I22: =0 -> 0 | J22: ='P08 DMSTrucking Output'!$J$11 -> 2.7523996 | K22: ='P08 DMSTrucking Output'!$M$11 -> 3.5746249 | L22: ='P08 DMSTrucking Output'!$M$15 -> 2.8596999 | M22: ='P08 DMSTrucking Output'!$E$47 -> 23.736572 | N22: =IF(ISNUMBER('P08 DMSTrucking Output'!$E$49),'P08 DMSTrucking Output'!$E$49,"n/a") -> n/a | O22: =IF(ISNUMBER('P08 DMSTrucking Output'!$E$52),'P08 DMSTrucking Output'!$E$52,"n/a") -> n/a | P22: open | Q22: open | R22: open
B23: P12 BUMN operatorship schemes (Pelindo Teluk Lamong, KBS Cigading, Pelindo Belawan) | C23: BUMN synergy | D23: ='Global Inputs'!$E$100 -> 1 | E23: ='Global Inputs'!$F$100 -> 2 | F23: ='Global Inputs'!$G$100 -> 1 | G23: ='P12 BUMNOps Input'!$E$25 -> 2026 | H23: =0 -> 0 | I23: =0 -> 0 | J23: ='P12 BUMNOps Output'!$J$11 -> 134.53638 | K23: ='P12 BUMNOps Output'!$M$11 -> 149.12654 | L23: ='P12 BUMNOps Output'!$M$15 -> 68.059001 | M23: ='P12 BUMNOps Output'!$E$47 -> 532.3041 | N23: =IF(ISNUMBER('P12 BUMNOps Output'!$E$49),'P12 BUMNOps Output'!$E$49,"n/a") -> n/a | O23: =IF(ISNUMBER('P12 BUMNOps Output'!$E$52),'P12 BUMNOps Output'!$E$52,"n/a") -> n/a | P23: open | Q23: open | R23: open
B24: P15 TBM — Tanjung Batu / Pelindo land lease, warehousing and cargo handling | C24: Pipeline (excluded by default) | D24: ='Global Inputs'!$E$101 -> 0 | E24: ='Global Inputs'!$F$101 -> 1 | F24: ='Global Inputs'!$G$101 -> 1 | G24: ='P15 TBM Input'!$E$25 -> 2027 | H24: ='P15 TBM Input'!$E$53 -> 40.024593 | I24: ='P15 TBM Input'!$E$59 -> 0 | J24: ='P15 TBM Output'!$J$11 -> 0 | K24: ='P15 TBM Output'!$M$11 -> 374.7552 | L24: ='P15 TBM Output'!$M$15 -> 199.11267 | M24: ='P15 TBM Output'!$E$47 -> 1325.7316 | N24: =IF(ISNUMBER('P15 TBM Output'!$E$49),'P15 TBM Output'!$E$49,"n/a") -> 0.095422425 | O24: =IF(ISNUMBER('P15 TBM Output'!$E$52),'P15 TBM Output'!$E$52,"n/a") -> 2033 | P24: open | Q24: open | R24: open
B25: P19 Badas bulk terminal (FS pending — DUMMY data) | C25: Pipeline — FS pending (DUMMY inputs, excluded from headline valuation) | D25: ='Global Inputs'!$E$102 -> 0 | E25: ='Global Inputs'!$F$102 -> 1 | F25: ='Global Inputs'!$G$102 -> 1 | G25: ='P19 Badas FS Working Paper'!$E$25 -> 2029 | H25: ='P19 Badas FS Working Paper'!$E$57 -> 10 | I25: ='P19 Badas FS Working Paper'!$E$63 -> 10 | J25: ='P19 Badas Output'!$J$11 -> 0 | K25: ='P19 Badas Output'!$M$11 -> 37.96065 | L25: ='P19 Badas Output'!$M$15 -> 18.243868 | M25: ='P19 Badas Output'!$E$47 -> 35.230684 | N25: =IF(ISNUMBER('P19 Badas Output'!$E$49),'P19 Badas Output'!$E$49,"n/a") -> 0.0036863533 | O25: =IF(ISNUMBER('P19 Badas Output'!$E$52),'P19 Badas Output'!$E$52,"n/a") -> 2036 | P25: open | Q25: open | R25: open
B26: Total (all projects listed, before case flags) | H26: =SUM(H12:H25) -> 106.47019 | I26: =SUM(I12:I25) -> 19.837296 | J26: =SUM(J12:J25) -> 754.46249 | K26: =SUM(K12:K25) -> 1369.7323 | L26: =SUM(L12:L25) -> 792.72226 | M26: =SUM(M12:M25) -> 6228.2816
B28: B. Bridge: sum of project outputs -> company statements (both cases; IDR bn)
B29: Sum of project revenue x Without-BUMN flags | C29: IDR bn | F29: ='E1 TelukLamong Output'!F11*'Global Inputs'!$K$89+'E2 CigadingExist Output'!F11*'Global Inputs'!$K$90+'E3 Belawan Output'!F11*'Global Inputs'!$K$91+'E4 WIN Output'!F11*'Global Inputs'!$K$92+'P01 CigWharf2 Output'!F11*'Global Inputs'!$K$93+'P02 CigConveyor Output'!F11*'Global Inputs'!$K$94+'P03 KBSWarehouse Output'!F11*'Global Inputs'!$K$95+'P04 TTLSilo Output'!F11*'Global Inputs'!$K$96+'P05 Dumai Output'!F11*'Global Inputs'!$K$97+'P06 Ciwandan Output'!F11*'Global Inputs'!$K$98+'P08 DMSTrucking Output'!F11*'Global Inputs'!$K$99+'P12 BUMNOps Output'!F11*'Global Inputs'!$K$100+'P15 TBM Output'!F11*'Global Inputs'!$K$101+'P19 Badas Output'!F11*'Global Inputs'!$K$102 -> 0 | G29: ='E1 TelukLamong Output'!G11*'Global Inputs'!$K$89+'E2 CigadingExist Output'!G11*'Global Inputs'!$K$90+'E3 Belawan Output'!G11*'Global Inputs'!$K$91+'E4 WIN Output'!G11*'Global Inputs'!$K$92+'P01 CigWharf2 Output'!G11*'Global Inputs'!$K$93+'P02 CigConveyor Output'!G11*'Global Inputs'!$K$94+'P03 KBSWarehouse Output'!G11*'Global Inputs'!$K$95+'P04 TTLSilo Output'!G11*'Global Inputs'!$K$96+'P05 Dumai Output'!G11*'Global Inputs'!$K$97+'P06 Ciwandan Output'!G11*'Global Inputs'!$K$98+'P08 DMSTrucking Output'!G11*'Global Inputs'!$K$99+'P12 BUMNOps Output'!G11*'Global Inputs'!$K$100+'P15 TBM Output'!G11*'Global Inputs'!$K$101+'P19 Badas Output'!G11*'Global Inputs'!$K$102 -> 305.28841 | H29: ='E1 TelukLamong Output'!H11*'Global Inputs'!$K$89+'E2 CigadingExist Output'!H11*'Global Inputs'!$K$90+'E3 Belawan Output'!H11*'Global Inputs'!$K$91+'E4 WIN Output'!H11*'Global Inputs'!$K$92+'P01 CigWharf2 Output'!H11*'Global Inputs'!$K$93+'P02 CigConveyor Output'!H11*'Global Inputs'!$K$94+'P03 KBSWarehouse Output'!H11*'Global Inputs'!$K$95+'P04 TTLSilo Output'!H11*'Global Inputs'!$K$96+'P05 Dumai Output'!H11*'Global Inputs'!$K$97+'P06 Ciwandan Output'!H11*'Global Inputs'!$K$98+'P08 DMSTrucking Output'!H11*'Global Inputs'!$K$99+'P12 BUMNOps Output'!H11*'Global Inputs'!$K$100+'P15 TBM Output'!H11*'Global Inputs'!$K$101+'P19 Badas Output'!H11*'Global Inputs'!$K$102 -> 427.60264 | I29: ='E1 TelukLamong Output'!I11*'Global Inputs'!$K$89+'E2 CigadingExist Output'!I11*'Global Inputs'!$K$90+'E3 Belawan Output'!I11*'Global Inputs'!$K$91+'E4 WIN Output'!I11*'Global Inputs'!$K$92+'P01 CigWharf2 Output'!I11*'Global Inputs'!$K$93+'P02 CigConveyor Output'!I11*'Global Inputs'!$K$94+'P03 KBSWarehouse Output'!I11*'Global Inputs'!$K$95+'P04 TTLSilo Output'!I11*'Global Inputs'!$K$96+'P05 Dumai Output'!I11*'Global Inputs'!$K$97+'P06 Ciwandan Output'!I11*'Global Inputs'!$K$98+'P08 DMSTrucking Output'!I11*'Global Inputs'!$K$99+'P12 BUMNOps Output'!I11*'Global Inputs'!$K$100+'P15 TBM Output'!I11*'Global Inputs'!$K$101+'P19 Badas Output'!I11*'Global Inputs'!$K$102 -> 494.57084 | J29: ='E1 TelukLamong Output'!J11*'Global Inputs'!$K$89+'E2 CigadingExist Output'!J11*'Global Inputs'!$K$90+'E3 Belawan Output'!J11*'Global Inputs'!$K$91+'E4 WIN Output'!J11*'Global Inputs'!$K$92+'P01 CigWharf2 Output'!J11*'Global Inputs'!$K$93+'P02 CigConveyor Output'!J11*'Global Inputs'!$K$94+'P03 KBSWarehouse Output'!J11*'Global Inputs'!$K$95+'P04 TTLSilo Output'!J11*'Global Inputs'!$K$96+'P05 Dumai Output'!J11*'Global Inputs'!$K$97+'P06 Ciwandan Output'!J11*'Global Inputs'!$K$98+'P08 DMSTrucking Output'!J11*'Global Inputs'!$K$99+'P12 BUMNOps Output'!J11*'Global Inputs'!$K$100+'P15 TBM Output'!J11*'Global Inputs'!$K$101+'P19 Badas Output'!J11*'Global Inputs'!$K$102 -> 619.92611 | K29: ='E1 TelukLamong Output'!K11*'Global Inputs'!$K$89+'E2 CigadingExist Output'!K11*'Global Inputs'!$K$90+'E3 Belawan Output'!K11*'Global Inputs'!$K$91+'E4 WIN Output'!K11*'Global Inputs'!$K$92+'P01 CigWharf2 Output'!K11*'Global Inputs'!$K$93+'P02 CigConveyor Output'!K11*'Global Inputs'!$K$94+'P03 KBSWarehouse Output'!K11*'Global Inputs'!$K$95+'P04 TTLSilo Output'!K11*'Global Inputs'!$K$96+'P05 Dumai Output'!K11*'Global Inputs'!$K$97+'P06 Ciwandan Output'!K11*'Global Inputs'!$K$98+'P08 DMSTrucking Output'!K11*'Global Inputs'!$K$99+'P12 BUMNOps Output'!K11*'Global Inputs'!$K$100+'P15 TBM Output'!K11*'Global Inputs'!$K$101+'P19 Badas Output'!K11*'Global Inputs'!$K$102 -> 702.02883 | L29: ='E1 TelukLamong Output'!L11*'Global Inputs'!$K$89+'E2 CigadingExist Output'!L11*'Global Inputs'!$K$90+'E3 Belawan Output'!L11*'Global Inputs'!$K$91+'E4 WIN Output'!L11*'Global Inputs'!$K$92+'P01 CigWharf2 Output'!L11*'Global Inputs'!$K$93+'P02 CigConveyor Output'!L11*'Global Inputs'!$K$94+'P03 KBSWarehouse Output'!L11*'Global Inputs'!$K$95+'P04 TTLSilo Output'!L11*'Global Inputs'!$K$96+'P05 Dumai Output'!L11*'Global Inputs'!$K$97+'P06 Ciwandan Output'!L11*'Global Inputs'!$K$98+'P08 DMSTrucking Output'!L11*'Global Inputs'!$K$99+'P12 BUMNOps Output'!L11*'Global Inputs'!$K$100+'P15 TBM Output'!L11*'Global Inputs'!$K$101+'P19 Badas Output'!L11*'Global Inputs'!$K$102 -> 773.76406 | M29: ='E1 TelukLamong Output'!M11*'Global Inputs'!$K$89+'E2 CigadingExist Output'!M11*'Global Inputs'!$K$90+'E3 Belawan Output'!M11*'Global Inputs'!$K$91+'E4 WIN Output'!M11*'Global Inputs'!$K$92+'P01 CigWharf2 Output'!M11*'Global Inputs'!$K$93+'P02 CigConveyor Output'!M11*'Global Inputs'!$K$94+'P03 KBSWarehouse Output'!M11*'Global Inputs'!$K$95+'P04 TTLSilo Output'!M11*'Global Inputs'!$K$96+'P05 Dumai Output'!M11*'Global Inputs'!$K$97+'P06 Ciwandan Output'!M11*'Global Inputs'!$K$98+'P08 DMSTrucking Output'!M11*'Global Inputs'!$K$99+'P12 BUMNOps Output'!M11*'Global Inputs'!$K$100+'P15 TBM Output'!M11*'Global Inputs'!$K$101+'P19 Badas Output'!M11*'Global Inputs'!$K$102 -> 807.88996 | ... S29: ='E1 TelukLamong Output'!S11*'Global Inputs'!$K$89+'E2 CigadingExist Output'!S11*'Global Inputs'!$K$90+'E3 Belawan Output'!S11*'Global Inputs'!$K$91+'E4 WIN Output'!S11*'Global Inputs'!$K$92+'P01 CigWharf2 Output'!S11*'Global Inputs'!$K$93+'P02 CigConveyor Output'!S11*'Global Inputs'!$K$94+'P03 KBSWarehouse Output'!S11*'Global Inputs'!$K$95+'P04 TTLSilo Output'!S11*'Global Inputs'!$K$96+'P05 Dumai Output'!S11*'Global Inputs'!$K$97+'P06 Ciwandan Output'!S11*'Global Inputs'!$K$98+'P08 DMSTrucking Output'!S11*'Global Inputs'!$K$99+'P12 BUMNOps Output'!S11*'Global Inputs'!$K$100+'P15 TBM Output'!S11*'Global Inputs'!$K$101+'P19 Badas Output'!S11*'Global Inputs'!$K$102 -> 1040.9483
B30: FSL Financials — Without BUMN revenue | C30: IDR bn | F30: ='FSL Financials — Without BUMN'!F18 -> 0 | G30: ='FSL Financials — Without BUMN'!G18 -> 305.28841 | H30: ='FSL Financials — Without BUMN'!H18 -> 427.60264 | I30: ='FSL Financials — Without BUMN'!I18 -> 494.57084 | J30: ='FSL Financials — Without BUMN'!J18 -> 619.92611 | K30: ='FSL Financials — Without BUMN'!K18 -> 702.02883 | L30: ='FSL Financials — Without BUMN'!L18 -> 773.76406 | M30: ='FSL Financials — Without BUMN'!M18 -> 807.88996 | ... S30: ='FSL Financials — Without BUMN'!S18 -> 1040.9483
B31: Difference | C31: IDR bn | F31: =F29-F30 -> 0 | G31: =G29-G30 -> 0 | H31: =H29-H30 -> 0 | I31: =I29-I30 -> 0 | J31: =J29-J30 -> 0 | K31: =K29-K30 -> 0 | L31: =L29-L30 -> 0 | M31: =M29-M30 -> 0 | ... S31: =S29-S30 -> 0
B32: Sum of project revenue x With-BUMN flags | C32: IDR bn | F32: ='E1 TelukLamong Output'!F11*'Global Inputs'!$L$89+'E2 CigadingExist Output'!F11*'Global Inputs'!$L$90+'E3 Belawan Output'!F11*'Global Inputs'!$L$91+'E4 WIN Output'!F11*'Global Inputs'!$L$92+'P01 CigWharf2 Output'!F11*'Global Inputs'!$L$93+'P02 CigConveyor Output'!F11*'Global Inputs'!$L$94+'P03 KBSWarehouse Output'!F11*'Global Inputs'!$L$95+'P04 TTLSilo Output'!F11*'Global Inputs'!$L$96+'P05 Dumai Output'!F11*'Global Inputs'!$L$97+'P06 Ciwandan Output'!F11*'Global Inputs'!$L$98+'P08 DMSTrucking Output'!F11*'Global Inputs'!$L$99+'P12 BUMNOps Output'!F11*'Global Inputs'!$L$100+'P15 TBM Output'!F11*'Global Inputs'!$L$101+'P19 Badas Output'!F11*'Global Inputs'!$L$102 -> 0 | G32: ='E1 TelukLamong Output'!G11*'Global Inputs'!$L$89+'E2 CigadingExist Output'!G11*'Global Inputs'!$L$90+'E3 Belawan Output'!G11*'Global Inputs'!$L$91+'E4 WIN Output'!G11*'Global Inputs'!$L$92+'P01 CigWharf2 Output'!G11*'Global Inputs'!$L$93+'P02 CigConveyor Output'!G11*'Global Inputs'!$L$94+'P03 KBSWarehouse Output'!G11*'Global Inputs'!$L$95+'P04 TTLSilo Output'!G11*'Global Inputs'!$L$96+'P05 Dumai Output'!G11*'Global Inputs'!$L$97+'P06 Ciwandan Output'!G11*'Global Inputs'!$L$98+'P08 DMSTrucking Output'!G11*'Global Inputs'!$L$99+'P12 BUMNOps Output'!G11*'Global Inputs'!$L$100+'P15 TBM Output'!G11*'Global Inputs'!$L$101+'P19 Badas Output'!G11*'Global Inputs'!$L$102 -> 305.28841 | H32: ='E1 TelukLamong Output'!H11*'Global Inputs'!$L$89+'E2 CigadingExist Output'!H11*'Global Inputs'!$L$90+'E3 Belawan Output'!H11*'Global Inputs'!$L$91+'E4 WIN Output'!H11*'Global Inputs'!$L$92+'P01 CigWharf2 Output'!H11*'Global Inputs'!$L$93+'P02 CigConveyor Output'!H11*'Global Inputs'!$L$94+'P03 KBSWarehouse Output'!H11*'Global Inputs'!$L$95+'P04 TTLSilo Output'!H11*'Global Inputs'!$L$96+'P05 Dumai Output'!H11*'Global Inputs'!$L$97+'P06 Ciwandan Output'!H11*'Global Inputs'!$L$98+'P08 DMSTrucking Output'!H11*'Global Inputs'!$L$99+'P12 BUMNOps Output'!H11*'Global Inputs'!$L$100+'P15 TBM Output'!H11*'Global Inputs'!$L$101+'P19 Badas Output'!H11*'Global Inputs'!$L$102 -> 427.60264 | I32: ='E1 TelukLamong Output'!I11*'Global Inputs'!$L$89+'E2 CigadingExist Output'!I11*'Global Inputs'!$L$90+'E3 Belawan Output'!I11*'Global Inputs'!$L$91+'E4 WIN Output'!I11*'Global Inputs'!$L$92+'P01 CigWharf2 Output'!I11*'Global Inputs'!$L$93+'P02 CigConveyor Output'!I11*'Global Inputs'!$L$94+'P03 KBSWarehouse Output'!I11*'Global Inputs'!$L$95+'P04 TTLSilo Output'!I11*'Global Inputs'!$L$96+'P05 Dumai Output'!I11*'Global Inputs'!$L$97+'P06 Ciwandan Output'!I11*'Global Inputs'!$L$98+'P08 DMSTrucking Output'!I11*'Global Inputs'!$L$99+'P12 BUMNOps Output'!I11*'Global Inputs'!$L$100+'P15 TBM Output'!I11*'Global Inputs'!$L$101+'P19 Badas Output'!I11*'Global Inputs'!$L$102 -> 622.06456 | J32: ='E1 TelukLamong Output'!J11*'Global Inputs'!$L$89+'E2 CigadingExist Output'!J11*'Global Inputs'!$L$90+'E3 Belawan Output'!J11*'Global Inputs'!$L$91+'E4 WIN Output'!J11*'Global Inputs'!$L$92+'P01 CigWharf2 Output'!J11*'Global Inputs'!$L$93+'P02 CigConveyor Output'!J11*'Global Inputs'!$L$94+'P03 KBSWarehouse Output'!J11*'Global Inputs'!$L$95+'P04 TTLSilo Output'!J11*'Global Inputs'!$L$96+'P05 Dumai Output'!J11*'Global Inputs'!$L$97+'P06 Ciwandan Output'!J11*'Global Inputs'!$L$98+'P08 DMSTrucking Output'!J11*'Global Inputs'!$L$99+'P12 BUMNOps Output'!J11*'Global Inputs'!$L$100+'P15 TBM Output'!J11*'Global Inputs'!$L$101+'P19 Badas Output'!J11*'Global Inputs'!$L$102 -> 754.46249 | K32: ='E1 TelukLamong Output'!K11*'Global Inputs'!$L$89+'E2 CigadingExist Output'!K11*'Global Inputs'!$L$90+'E3 Belawan Output'!K11*'Global Inputs'!$L$91+'E4 WIN Output'!K11*'Global Inputs'!$L$92+'P01 CigWharf2 Output'!K11*'Global Inputs'!$L$93+'P02 CigConveyor Output'!K11*'Global Inputs'!$L$94+'P03 KBSWarehouse Output'!K11*'Global Inputs'!$L$95+'P04 TTLSilo Output'!K11*'Global Inputs'!$L$96+'P05 Dumai Output'!K11*'Global Inputs'!$L$97+'P06 Ciwandan Output'!K11*'Global Inputs'!$L$98+'P08 DMSTrucking Output'!K11*'Global Inputs'!$L$99+'P12 BUMNOps Output'!K11*'Global Inputs'!$L$100+'P15 TBM Output'!K11*'Global Inputs'!$L$101+'P19 Badas Output'!K11*'Global Inputs'!$L$102 -> 841.30923 | L32: ='E1 TelukLamong Output'!L11*'Global Inputs'!$L$89+'E2 CigadingExist Output'!L11*'Global Inputs'!$L$90+'E3 Belawan Output'!L11*'Global Inputs'!$L$91+'E4 WIN Output'!L11*'Global Inputs'!$L$92+'P01 CigWharf2 Output'!L11*'Global Inputs'!$L$93+'P02 CigConveyor Output'!L11*'Global Inputs'!$L$94+'P03 KBSWarehouse Output'!L11*'Global Inputs'!$L$95+'P04 TTLSilo Output'!L11*'Global Inputs'!$L$96+'P05 Dumai Output'!L11*'Global Inputs'!$L$97+'P06 Ciwandan Output'!L11*'Global Inputs'!$L$98+'P08 DMSTrucking Output'!L11*'Global Inputs'!$L$99+'P12 BUMNOps Output'!L11*'Global Inputs'!$L$100+'P15 TBM Output'!L11*'Global Inputs'!$L$101+'P19 Badas Output'!L11*'Global Inputs'!$L$102 -> 917.90667 | M32: ='E1 TelukLamong Output'!M11*'Global Inputs'!$L$89+'E2 CigadingExist Output'!M11*'Global Inputs'!$L$90+'E3 Belawan Output'!M11*'Global Inputs'!$L$91+'E4 WIN Output'!M11*'Global Inputs'!$L$92+'P01 CigWharf2 Output'!M11*'Global Inputs'!$L$93+'P02 CigConveyor Output'!M11*'Global Inputs'!$L$94+'P03 KBSWarehouse Output'!M11*'Global Inputs'!$L$95+'P04 TTLSilo Output'!M11*'Global Inputs'!$L$96+'P05 Dumai Output'!M11*'Global Inputs'!$L$97+'P06 Ciwandan Output'!M11*'Global Inputs'!$L$98+'P08 DMSTrucking Output'!M11*'Global Inputs'!$L$99+'P12 BUMNOps Output'!M11*'Global Inputs'!$L$100+'P15 TBM Output'!M11*'Global Inputs'!$L$101+'P19 Badas Output'!M11*'Global Inputs'!$L$102 -> 957.0165 | ... S32: ='E1 TelukLamong Output'!S11*'Global Inputs'!$L$89+'E2 CigadingExist Output'!S11*'Global Inputs'!$L$90+'E3 Belawan Output'!S11*'Global Inputs'!$L$91+'E4 WIN Output'!S11*'Global Inputs'!$L$92+'P01 CigWharf2 Output'!S11*'Global Inputs'!$L$93+'P02 CigConveyor Output'!S11*'Global Inputs'!$L$94+'P03 KBSWarehouse Output'!S11*'Global Inputs'!$L$95+'P04 TTLSilo Output'!S11*'Global Inputs'!$L$96+'P05 Dumai Output'!S11*'Global Inputs'!$L$97+'P06 Ciwandan Output'!S11*'Global Inputs'!$L$98+'P08 DMSTrucking Output'!S11*'Global Inputs'!$L$99+'P12 BUMNOps Output'!S11*'Global Inputs'!$L$100+'P15 TBM Output'!S11*'Global Inputs'!$L$101+'P19 Badas Output'!S11*'Global Inputs'!$L$102 -> 1212.2892
B33: FSL Financials — With BUMN revenue | C33: IDR bn | F33: ='FSL Financials — With BUMN'!F18 -> 0 | G33: ='FSL Financials — With BUMN'!G18 -> 305.28841 | H33: ='FSL Financials — With BUMN'!H18 -> 427.60264 | I33: ='FSL Financials — With BUMN'!I18 -> 622.06456 | J33: ='FSL Financials — With BUMN'!J18 -> 754.46249 | K33: ='FSL Financials — With BUMN'!K18 -> 841.30923 | L33: ='FSL Financials — With BUMN'!L18 -> 917.90667 | M33: ='FSL Financials — With BUMN'!M18 -> 957.0165 | ... S33: ='FSL Financials — With BUMN'!S18 -> 1212.2892
B34: Difference | C34: IDR bn | F34: =F32-F33 -> 0 | G34: =G32-G33 -> 0 | H34: =H32-H33 -> 0 | I34: =I32-I33 -> 0 | J34: =J32-J33 -> 0 | K34: =K32-K33 -> 0 | L34: =L32-L33 -> 0 | M34: =M32-M33 -> 0 | ... S34: =S32-S33 -> 0
B35: Sum of project FCFF x With-BUMN flags | C35: IDR bn | F35: ='E1 TelukLamong Output'!F28*'Global Inputs'!$L$89+'E2 CigadingExist Output'!F28*'Global Inputs'!$L$90+'E3 Belawan Output'!F28*'Global Inputs'!$L$91+'E4 WIN Output'!F28*'Global Inputs'!$L$92+'P01 CigWharf2 Output'!F28*'Global Inputs'!$L$93+'P02 CigConveyor Output'!F28*'Global Inputs'!$L$94+'P03 KBSWarehouse Output'!F28*'Global Inputs'!$L$95+'P04 TTLSilo Output'!F28*'Global Inputs'!$L$96+'P05 Dumai Output'!F28*'Global Inputs'!$L$97+'P06 Ciwandan Output'!F28*'Global Inputs'!$L$98+'P08 DMSTrucking Output'!F28*'Global Inputs'!$L$99+'P12 BUMNOps Output'!F28*'Global Inputs'!$L$100+'P15 TBM Output'!F28*'Global Inputs'!$L$101+'P19 Badas Output'!F28*'Global Inputs'!$L$102 -> -198.433 | G35: ='E1 TelukLamong Output'!G28*'Global Inputs'!$L$89+'E2 CigadingExist Output'!G28*'Global Inputs'!$L$90+'E3 Belawan Output'!G28*'Global Inputs'!$L$91+'E4 WIN Output'!G28*'Global Inputs'!$L$92+'P01 CigWharf2 Output'!G28*'Global Inputs'!$L$93+'P02 CigConveyor Output'!G28*'Global Inputs'!$L$94+'P03 KBSWarehouse Output'!G28*'Global Inputs'!$L$95+'P04 TTLSilo Output'!G28*'Global Inputs'!$L$96+'P05 Dumai Output'!G28*'Global Inputs'!$L$97+'P06 Ciwandan Output'!G28*'Global Inputs'!$L$98+'P08 DMSTrucking Output'!G28*'Global Inputs'!$L$99+'P12 BUMNOps Output'!G28*'Global Inputs'!$L$100+'P15 TBM Output'!G28*'Global Inputs'!$L$101+'P19 Badas Output'!G28*'Global Inputs'!$L$102 -> 11.8696 | H35: ='E1 TelukLamong Output'!H28*'Global Inputs'!$L$89+'E2 CigadingExist Output'!H28*'Global Inputs'!$L$90+'E3 Belawan Output'!H28*'Global Inputs'!$L$91+'E4 WIN Output'!H28*'Global Inputs'!$L$92+'P01 CigWharf2 Output'!H28*'Global Inputs'!$L$93+'P02 CigConveyor Output'!H28*'Global Inputs'!$L$94+'P03 KBSWarehouse Output'!H28*'Global Inputs'!$L$95+'P04 TTLSilo Output'!H28*'Global Inputs'!$L$96+'P05 Dumai Output'!H28*'Global Inputs'!$L$97+'P06 Ciwandan Output'!H28*'Global Inputs'!$L$98+'P08 DMSTrucking Output'!H28*'Global Inputs'!$L$99+'P12 BUMNOps Output'!H28*'Global Inputs'!$L$100+'P15 TBM Output'!H28*'Global Inputs'!$L$101+'P19 Badas Output'!H28*'Global Inputs'!$L$102 -> 196.17207 | I35: ='E1 TelukLamong Output'!I28*'Global Inputs'!$L$89+'E2 CigadingExist Output'!I28*'Global Inputs'!$L$90+'E3 Belawan Output'!I28*'Global Inputs'!$L$91+'E4 WIN Output'!I28*'Global Inputs'!$L$92+'P01 CigWharf2 Output'!I28*'Global Inputs'!$L$93+'P02 CigConveyor Output'!I28*'Global Inputs'!$L$94+'P03 KBSWarehouse Output'!I28*'Global Inputs'!$L$95+'P04 TTLSilo Output'!I28*'Global Inputs'!$L$96+'P05 Dumai Output'!I28*'Global Inputs'!$L$97+'P06 Ciwandan Output'!I28*'Global Inputs'!$L$98+'P08 DMSTrucking Output'!I28*'Global Inputs'!$L$99+'P12 BUMNOps Output'!I28*'Global Inputs'!$L$100+'P15 TBM Output'!I28*'Global Inputs'!$L$101+'P19 Badas Output'!I28*'Global Inputs'!$L$102 -> -133.2095 | J35: ='E1 TelukLamong Output'!J28*'Global Inputs'!$L$89+'E2 CigadingExist Output'!J28*'Global Inputs'!$L$90+'E3 Belawan Output'!J28*'Global Inputs'!$L$91+'E4 WIN Output'!J28*'Global Inputs'!$L$92+'P01 CigWharf2 Output'!J28*'Global Inputs'!$L$93+'P02 CigConveyor Output'!J28*'Global Inputs'!$L$94+'P03 KBSWarehouse Output'!J28*'Global Inputs'!$L$95+'P04 TTLSilo Output'!J28*'Global Inputs'!$L$96+'P05 Dumai Output'!J28*'Global Inputs'!$L$97+'P06 Ciwandan Output'!J28*'Global Inputs'!$L$98+'P08 DMSTrucking Output'!J28*'Global Inputs'!$L$99+'P12 BUMNOps Output'!J28*'Global Inputs'!$L$100+'P15 TBM Output'!J28*'Global Inputs'!$L$101+'P19 Badas Output'!J28*'Global Inputs'!$L$102 -> 205.30586 | K35: ='E1 TelukLamong Output'!K28*'Global Inputs'!$L$89+'E2 CigadingExist Output'!K28*'Global Inputs'!$L$90+'E3 Belawan Output'!K28*'Global Inputs'!$L$91+'E4 WIN Output'!K28*'Global Inputs'!$L$92+'P01 CigWharf2 Output'!K28*'Global Inputs'!$L$93+'P02 CigConveyor Output'!K28*'Global Inputs'!$L$94+'P03 KBSWarehouse Output'!K28*'Global Inputs'!$L$95+'P04 TTLSilo Output'!K28*'Global Inputs'!$L$96+'P05 Dumai Output'!K28*'Global Inputs'!$L$97+'P06 Ciwandan Output'!K28*'Global Inputs'!$L$98+'P08 DMSTrucking Output'!K28*'Global Inputs'!$L$99+'P12 BUMNOps Output'!K28*'Global Inputs'!$L$100+'P15 TBM Output'!K28*'Global Inputs'!$L$101+'P19 Badas Output'!K28*'Global Inputs'!$L$102 -> 411.92011 | L35: ='E1 TelukLamong Output'!L28*'Global Inputs'!$L$89+'E2 CigadingExist Output'!L28*'Global Inputs'!$L$90+'E3 Belawan Output'!L28*'Global Inputs'!$L$91+'E4 WIN Output'!L28*'Global Inputs'!$L$92+'P01 CigWharf2 Output'!L28*'Global Inputs'!$L$93+'P02 CigConveyor Output'!L28*'Global Inputs'!$L$94+'P03 KBSWarehouse Output'!L28*'Global Inputs'!$L$95+'P04 TTLSilo Output'!L28*'Global Inputs'!$L$96+'P05 Dumai Output'!L28*'Global Inputs'!$L$97+'P06 Ciwandan Output'!L28*'Global Inputs'!$L$98+'P08 DMSTrucking Output'!L28*'Global Inputs'!$L$99+'P12 BUMNOps Output'!L28*'Global Inputs'!$L$100+'P15 TBM Output'!L28*'Global Inputs'!$L$101+'P19 Badas Output'!L28*'Global Inputs'!$L$102 -> 456.29206 | M35: ='E1 TelukLamong Output'!M28*'Global Inputs'!$L$89+'E2 CigadingExist Output'!M28*'Global Inputs'!$L$90+'E3 Belawan Output'!M28*'Global Inputs'!$L$91+'E4 WIN Output'!M28*'Global Inputs'!$L$92+'P01 CigWharf2 Output'!M28*'Global Inputs'!$L$93+'P02 CigConveyor Output'!M28*'Global Inputs'!$L$94+'P03 KBSWarehouse Output'!M28*'Global Inputs'!$L$95+'P04 TTLSilo Output'!M28*'Global Inputs'!$L$96+'P05 Dumai Output'!M28*'Global Inputs'!$L$97+'P06 Ciwandan Output'!M28*'Global Inputs'!$L$98+'P08 DMSTrucking Output'!M28*'Global Inputs'!$L$99+'P12 BUMNOps Output'!M28*'Global Inputs'!$L$100+'P15 TBM Output'!M28*'Global Inputs'!$L$101+'P19 Badas Output'!M28*'Global Inputs'!$L$102 -> 478.00691 | ... S35: ='E1 TelukLamong Output'!S28*'Global Inputs'!$L$89+'E2 CigadingExist Output'!S28*'Global Inputs'!$L$90+'E3 Belawan Output'!S28*'Global Inputs'!$L$91+'E4 WIN Output'!S28*'Global Inputs'!$L$92+'P01 CigWharf2 Output'!S28*'Global Inputs'!$L$93+'P02 CigConveyor Output'!S28*'Global Inputs'!$L$94+'P03 KBSWarehouse Output'!S28*'Global Inputs'!$L$95+'P04 TTLSilo Output'!S28*'Global Inputs'!$L$96+'P05 Dumai Output'!S28*'Global Inputs'!$L$97+'P06 Ciwandan Output'!S28*'Global Inputs'!$L$98+'P08 DMSTrucking Output'!S28*'Global Inputs'!$L$99+'P12 BUMNOps Output'!S28*'Global Inputs'!$L$100+'P15 TBM Output'!S28*'Global Inputs'!$L$101+'P19 Badas Output'!S28*'Global Inputs'!$L$102 -> 596.57744
B36: Valuation — With BUMN FCFF | C36: IDR bn | F36: ='Valuation — With BUMN'!F31 -> -198.433 | G36: ='Valuation — With BUMN'!G31 -> 11.8696 | H36: ='Valuation — With BUMN'!H31 -> 196.17207 | I36: ='Valuation — With BUMN'!I31 -> -133.2095 | J36: ='Valuation — With BUMN'!J31 -> 205.30586 | K36: ='Valuation — With BUMN'!K31 -> 411.92011 | L36: ='Valuation — With BUMN'!L31 -> 456.29206 | M36: ='Valuation — With BUMN'!M31 -> 478.00691 | ... S36: ='Valuation — With BUMN'!S31 -> 596.57744
B37: Difference | C37: IDR bn | F37: =F35-F36 -> 0 | G37: =G35-G36 -> 0 | H37: =H35-H36 -> 0 | I37: =I35-I36 -> 0 | J37: =J35-J36 -> 0 | K37: =K35-K36 -> 0 | L37: =L35-L36 -> 0 | M37: =M35-M36 -> 0 | ... S37: =S35-S36 -> 0
B38: Company statements add corporate items (LT loan interest and its tax shield, dividends, injection, existing fixed assets, other balances) to the project sums; unlevered FCFF is identical by construction.
B40: E1 Teluk Lamong (NPLOG) cargodoring & delivery — Existing business — NPLOG Teluk Lamong
B41: Existing grain and meal terminal operations at Teluk Lamong (conveyor, warehouse, delivery): volume x tariff for meals and grains; variable costs per ton indexed from FY2023; fixed G&A lines; depreciation of existing assets. | C41: Input | D41: Calc | E41: Output | G41: ="In valuation: "&'Global Inputs'!$E$89&" | case: "&'Global Inputs'!$F$89&" | FSL interest: "&TEXT('Global Inputs'!$G$89,"0%") -> In valuation: 1 | case: 1 | FSL interest: 65%
B42: Revenue | C42: IDR bn | E42: =SUM(F42:S42) -> 2524.1108 | F42: ='E1 TelukLamong Output'!F11 -> 0 | G42: ='E1 TelukLamong Output'!G11 -> 156.43828 | H42: ='E1 TelukLamong Output'!H11 -> 161.13143 | I42: ='E1 TelukLamong Output'!I11 -> 165.96537 | J42: ='E1 TelukLamong Output'!J11 -> 170.94433 | K42: ='E1 TelukLamong Output'!K11 -> 176.07266 | L42: ='E1 TelukLamong Output'!L11 -> 186.79549 | M42: ='E1 TelukLamong Output'!M11 -> 192.39935 | ... S42: ='E1 TelukLamong Output'!S11 -> 236.62693
B43: EBITDA | C43: IDR bn | E43: =SUM(F43:S43) -> 1786.3683 | F43: ='E1 TelukLamong Output'!F15 -> 0 | G43: ='E1 TelukLamong Output'!G15 -> 112.5106 | H43: ='E1 TelukLamong Output'!H15 -> 115.41862 | I43: ='E1 TelukLamong Output'!I15 -> 118.36361 | J43: ='E1 TelukLamong Output'!J15 -> 121.38819 | K43: ='E1 TelukLamong Output'!K15 -> 124.47096 | L43: ='E1 TelukLamong Output'!L15 -> 133.03108 | M43: ='E1 TelukLamong Output'!M15 -> 136.39274 | ... S43: ='E1 TelukLamong Output'!S15 -> 164.71608
B44: EBIT | C44: IDR bn | E44: =SUM(F44:S44) -> 1219.2782 | F44: ='E1 TelukLamong Output'!F17 -> 0 | G44: ='E1 TelukLamong Output'!G17 -> 70.769814 | H44: ='E1 TelukLamong Output'!H17 -> 73.672367 | I44: ='E1 TelukLamong Output'!I17 -> 75.611774 | J44: ='E1 TelukLamong Output'!J17 -> 78.630654 | K44: ='E1 TelukLamong Output'!K17 -> 81.707618 | L44: ='E1 TelukLamong Output'!L17 -> 89.261806 | M44: ='E1 TelukLamong Output'!M17 -> 92.617426 | ... S44: ='E1 TelukLamong Output'!S17 -> 119.90188
...

Sheet FSL Financials — Without BUMN
B1: FSL FINANCIALS — WITHOUT BUMN (integrated income statement, balance sheet, cash flow)
B2: Sum of project outputs included in the Without-BUMN case + corporate items (LT loan, existing fixed assets, other balances). IDR bn. Green = link; black = formula.
B3: Go to: | C3: Navigation | D3: Global Inputs | E3: Project Summary | F3: Funding | G3: FSL w/o BUMN | H3: FSL w/ BUMN | I3: Val w/o BUMN | J3: Val w/ BUMN | K3: Checks | L3: Model Flow
B5: Year | C5: Unit | D5: Type | E5: Flag / total | F5: ='Global Inputs'!F$5 -> 2023 | G5: ='Global Inputs'!G$5 -> 2024 | H5: ='Global Inputs'!H$5 -> 2025 | I5: ='Global Inputs'!I$5 -> 2026 | J5: ='Global Inputs'!J$5 -> 2027 | K5: ='Global Inputs'!K$5 -> 2028 | L5: ='Global Inputs'!L$5 -> 2029 | M5: ='Global Inputs'!M$5 -> 2030 | ... S5: ='Global Inputs'!S$5 -> 2036 | T5: Source (v29 reference / basis) | U5: Note
